Workbook

Sheet BAHAN PANTAU
A1: BY NO KONTRAK | S1: VLOOKUP NAMA | AJ1: COPAS DARI SINI
A2: TANGAL INJECT | B2: DATA PRIORITY | C2: NAMA CABANG | D2: NO KONTRAK | E2: NAMA KONSUMEN | F2: KETERANGAN | G2: CUS ID | H2: PA | I2: ALAMAT | J2: KELURAHAN | K2: KECAMATAN | L2: GOOGLE MAP | M2: RATING | N2: CEK VISIT | O2: NO HP | S2: DATA PRIORITY | T2: NAMA CABANG | U2: NO KONTRAK | V2: NAMA KONSUMEN | W2: KETERANGAN | X2: CUS ID | Y2: PA | Z2: ALAMAT | AA2: KELURAHAN | AB2: KECAMATAN | AC2: GOOGLE MAP | AD2: RATING | AE2: CEK VISIT | AF2: NO HP | AJ2: TANGAL INJECT | AK2: DATA PRIORITY | AL2: NAMA CABANG | AM2: NO KONTRAK | AN2: NAMA KONSUMEN | AO2: KETERANGAN | AP2: CUS ID | AQ2: PA | AR2: ALAMAT | AS2: KELURAHAN | AT2: KECAMATAN | AU2: GOOGLE MAP | AV2: RATING | AW2: CEK VISIT | AX2: NO HP
B6: P2 | C6: KENDAL | D6: 1057120231106521 | E6: SUTARI | F6: Konsumen Aktif M 0 - 6 Lunas | G6: =VLOOKUP(D6,'DATABASE RO'!$B$3:$M$299,4,0) -> P257000002990 | H6: =VLOOKUP(D6,'DATABASE RO'!$B$3:$M$299,5,0) -> YES | I6: =VLOOKUP(D6,'DATABASE RO'!$B$3:$M$299,6,0) -> DUKUH KARANGANYAR RT 003 RW 003 KEDAWUNG BANYUPUTIH RT 003/003 RT 000 /RW 000, Kedawung, Banyuputih, KABUPATEN, 51271 | J6: =VLOOKUP(D6,'DATABASE RO'!$B$3:$M$299,7,0) -> Kedawung | K6: =VLOOKUP(D6,'DATABASE RO'!$B$3:$M$299,8,0) -> Banyuputih | L6: =VLOOKUP(D6,'DATABASE RO'!$B$3:$M$299,9,0) -> TIDAK ADA | M6: =VLOOKUP(D6,'DATABASE RO'!$B$3:$M$299,10,0) -> EXCELLENT | O6: =VLOOKUP(D6,'DATABASE RO'!$B$3:$M$299,12,0) -> 0852 - 26826959 | S6: =B6 -> P2 | T6: =C6 -> KENDAL | U6: =D6 -> 1057120231106521 | V6: =E6 -> SUTARI | X6: =VLOOKUP(V6,'DATABASE RO'!$C$3:$M$185,3,0) -> P257000002990 | Y6: =VLOOKUP(V6,'DATABASE RO'!$C$3:$M$185,4,0) -> YES | Z6: =VLOOKUP(V6,'DATABASE RO'!$C$3:$M$185,5,0) -> DUKUH KARANGANYAR RT 003 RW 003 KEDAWUNG BANYUPUTIH RT 003/003 RT 000 /RW 000, Kedawung, Banyuputih, KABUPATEN, 51271 | AA6: =VLOOKUP(V6,'DATABASE RO'!$C$3:$M$185,6,0) -> Kedawung | AB6: =VLOOKUP(V6,'DATABASE RO'!$C$3:$M$185,7,0) -> Banyuputih | AC6: =VLOOKUP(V6,'DATABASE RO'!$C$3:$M$185,8,0) -> TIDAK ADA | AD6: =VLOOKUP(V6,'DATABASE RO'!$C$3:$M$185,9,0) -> EXCELLENT | AF6: =VLOOKUP(V6,'DATABASE RO'!$C$3:$M$185,11,0) -> 0852 - 26826959 | AK6: =B6 -> P2 | AL6: =C6 -> KENDAL | AM6: =D6 -> 1057120231106521 | AN6: =E6 -> SUTARI | AO6: =F6 -> Konsumen Aktif M 0 - 6 Lunas | AP6: =IFERROR(G6,X6) -> P257000002990 | AQ6: =IFERROR(H6,Y6) -> YES | AR6: =IFERROR(I6,Z6) -> DUKUH KARANGANYAR RT 003 RW 003 KEDAWUNG BANYUPUTIH RT 003/003 RT 000 /RW 000, Kedawung, Banyuputih, KABUPATEN, 51271 | AS6: =IFERROR(J6,AA6) -> Kedawung | AT6: =IFERROR(K6,AB6) -> Banyuputih | AU6: =IFERROR(L6,AC6) -> TIDAK ADA | AV6: =IFERROR(M6,AD6) -> EXCELLENT | AW6: =IFERROR(N6,AE6) -> 0 | AX6: =IFERROR(O6,AF6) -> 0852 - 26826959
A7: VLOOKUP NAMA | B7: P2 | C7: KENDAL | D7: 1057120240206718 | E7: IRFAUDIN | F7: Konsumen Aktif M 0 - 6 Lunas | G7: =VLOOKUP(D7,'DATABASE RO'!$B$3:$M$299,4,0) -> #N/A | H7: =VLOOKUP(D7,'DATABASE RO'!$B$3:$M$299,5,0) -> #N/A | I7: =VLOOKUP(D7,'DATABASE RO'!$B$3:$M$299,6,0) -> #N/A | J7: =VLOOKUP(D7,'DATABASE RO'!$B$3:$M$299,7,0) -> #N/A | K7: =VLOOKUP(D7,'DATABASE RO'!$B$3:$M$299,8,0) -> #N/A | L7: =VLOOKUP(D7,'DATABASE RO'!$B$3:$M$299,9,0) -> #N/A | M7: =VLOOKUP(D7,'DATABASE RO'!$B$3:$M$299,10,0) -> #N/A | O7: =VLOOKUP(D7,'DATABASE RO'!$B$3:$M$299,12,0) -> #N/A | S7: =B7 -> P2 | T7: =C7 -> KENDAL | U7: =D7 -> 1057120240206718 | V7: =E7 -> IRFAUDIN | X7: =VLOOKUP(V7,'DATABASE RO'!$C$3:$M$185,3,0) -> #N/A | Y7: =VLOOKUP(V7,'DATABASE RO'!$C$3:$M$185,4,0) -> #N/A | Z7: =VLOOKUP(V7,'DATABASE RO'!$C$3:$M$185,5,0) -> #N/A | AA7: =VLOOKUP(V7,'DATABASE RO'!$C$3:$M$185,6,0) -> #N/A | AB7: =VLOOKUP(V7,'DATABASE RO'!$C$3:$M$185,7,0) -> #N/A | AC7: =VLOOKUP(V7,'DATABASE RO'!$C$3:$M$185,8,0) -> #N/A | AD7: =VLOOKUP(V7,'DATABASE RO'!$C$3:$M$185,9,0) -> #N/A | AF7: =VLOOKUP(V7,'DATABASE RO'!$C$3:$M$185,11,0) -> #N/A | AJ7: VLOOKUP NAMA | AK7: =B7 -> P2 | AL7: =C7 -> KENDAL | AM7: =D7 -> 1057120240206718 | AN7: =E7 -> IRFAUDIN | AO7: =F7 -> Konsumen Aktif M 0 - 6 Lunas | AP7: =IFERROR(G7,X7) -> #N/A | AQ7: =IFERROR(H7,Y7) -> #N/A | AR7: =IFERROR(I7,Z7) -> #N/A | AS7: =IFERROR(J7,AA7) -> #N/A | AT7: =IFERROR(K7,AB7) -> #N/A | AU7: =IFERROR(L7,AC7) -> #N/A | AV7: =IFERROR(M7,AD7) -> #N/A | AW7: =IFERROR(N7,AE7) -> 0 | AX7: =IFERROR(O7,AF7) -> #N/A
B8: P2 | C8: KENDAL | D8: 1057120251007882 | E8: JURIYAH | F8: Konsumen Aktif M 0 - 6 Lunas | G8: =VLOOKUP(D8,'DATABASE RO'!$B$3:$M$299,4,0) -> P057A002039893 | H8: =VLOOKUP(D8,'DATABASE RO'!$B$3:$M$299,5,0) -> YES | I8: =VLOOKUP(D8,'DATABASE RO'!$B$3:$M$299,6,0) -> PURBO RT 013 /RW 005, Purbo, Bawang, KAB-Batang, 51274 | J8: =VLOOKUP(D8,'DATABASE RO'!$B$3:$M$299,7,0) -> PURBO | K8: =VLOOKUP(D8,'DATABASE RO'!$B$3:$M$299,8,0) -> BAWANG | L8: =VLOOKUP(D8,'DATABASE RO'!$B$3:$M$299,9,0) -> google.com/maps?z=12&t=m&q=loc:-7.079575+109.934911 | M8: =VLOOKUP(D8,'DATABASE RO'!$B$3:$M$299,10,0) -> EXCELLENT | O8: =VLOOKUP(D8,'DATABASE RO'!$B$3:$M$299,12,0) -> 895417316985 | S8: =B8 -> P2 | T8: =C8 -> KENDAL | U8: =D8 -> 1057120251007882 | V8: =E8 -> JURIYAH | X8: =VLOOKUP(V8,'DATABASE RO'!$C$3:$M$185,3,0) -> P057A002039893 | Y8: =VLOOKUP(V8,'DATABASE RO'!$C$3:$M$185,4,0) -> YES | Z8: =VLOOKUP(V8,'DATABASE RO'!$C$3:$M$185,5,0) -> PURBO RT 013 /RW 005, Purbo, Bawang, KAB-Batang, 51274 | AA8: =VLOOKUP(V8,'DATABASE RO'!$C$3:$M$185,6,0) -> PURBO | AB8: =VLOOKUP(V8,'DATABASE RO'!$C$3:$M$185,7,0) -> BAWANG | AC8: =VLOOKUP(V8,'DATABASE RO'!$C$3:$M$185,8,0) -> google.com/maps?z=12&t=m&q=loc:-7.079575+109.934911 | AD8: =VLOOKUP(V8,'DATABASE RO'!$C$3:$M$185,9,0) -> EXCELLENT | AF8: =VLOOKUP(V8,'DATABASE RO'!$C$3:$M$185,11,0) -> 895417316985 | AK8: =B8 -> P2 | AL8: =C8 -> KENDAL | AM8: =D8 -> 1057120251007882 | AN8: =E8 -> JURIYAH | AO8: =F8 -> Konsumen Aktif M 0 - 6 Lunas | AP8: =IFERROR(G8,X8) -> P057A002039893 | AQ8: =IFERROR(H8,Y8) -> YES | AR8: =IFERROR(I8,Z8) -> PURBO RT 013 /RW 005, Purbo, Bawang, KAB-Batang, 51274 | AS8: =IFERROR(J8,AA8) -> PURBO | AT8: =IFERROR(K8,AB8) -> BAWANG | AU8: =IFERROR(L8,AC8) -> google.com/maps?z=12&t=m&q=loc:-7.079575+109.934911 | AV8: =IFERROR(M8,AD8) -> EXCELLENT | AW8: =IFERROR(N8,AE8) -> 0 | AX8: =IFERROR(O8,AF8) -> 895417316985
B9: P2 | C9: KENDAL | D9: 1061120250608474 | E9: HADI KURNIAWAN | F9: Konsumen Aktif M 0 - 6 Lunas | G9: =VLOOKUP(D9,'DATABASE RO'!$B$3:$M$299,4,0) -> P19002060234 | H9: =VLOOKUP(D9,'DATABASE RO'!$B$3:$M$299,5,0) -> NO | I9: =VLOOKUP(D9,'DATABASE RO'!$B$3:$M$299,6,0) -> WONOREJO RT 002/005 RT 000 /RW 000, Wonorejo, Kaliwungu, KABUPATEN, 51372 | J9: =VLOOKUP(D9,'DATABASE RO'!$B$3:$M$299,7,0) -> WONOREJO | K9: =VLOOKUP(D9,'DATABASE RO'!$B$3:$M$299,8,0) -> KALIWUNGU | L9: =VLOOKUP(D9,'DATABASE RO'!$B$3:$M$299,9,0) -> TIDAK ADA | M9: =VLOOKUP(D9,'DATABASE RO'!$B$3:$M$299,10,0) -> GOOD | O9: =VLOOKUP(D9,'DATABASE RO'!$B$3:$M$299,12,0) -> TIDAK ADA | S9: =B9 -> P2 | T9: =C9 -> KENDAL | U9: =D9 -> 1061120250608474 | V9: =E9 -> HADI KURNIAWAN | X9: =VLOOKUP(V9,'DATABASE RO'!$C$3:$M$185,3,0) -> P19002060234 | Y9: =VLOOKUP(V9,'DATABASE RO'!$C$3:$M$185,4,0) -> NO | Z9: =VLOOKUP(V9,'DATABASE RO'!$C$3:$M$185,5,0) -> WONOREJO RT 002/005 RT 000 /RW 000, Wonorejo, Kaliwungu, KABUPATEN, 51372 | AA9: =VLOOKUP(V9,'DATABASE RO'!$C$3:$M$185,6,0) -> WONOREJO | AB9: =VLOOKUP(V9,'DATABASE RO'!$C$3:$M$185,7,0) -> KALIWUNGU | AC9: =VLOOKUP(V9,'DATABASE RO'!$C$3:$M$185,8,0) -> TIDAK ADA | AD9: =VLOOKUP(V9,'DATABASE RO'!$C$3:$M$185,9,0) -> GOOD | AF9: =VLOOKUP(V9,'DATABASE RO'!$C$3:$M$185,11,0) -> TIDAK ADA | AK9: =B9 -> P2 | AL9: =C9 -> KENDAL | AM9: =D9 -> 1061120250608474 | AN9: =E9 -> HADI KURNIAWAN | AO9: =F9 -> Konsumen Aktif M 0 - 6 Lunas | AP9: =IFERROR(G9,X9) -> P19002060234 | AQ9: =IFERROR(H9,Y9) -> NO | AR9: =IFERROR(I9,Z9) -> WONOREJO RT 002/005 RT 000 /RW 000, Wonorejo, Kaliwungu, KABUPATEN, 51372 | AS9: =IFERROR(J9,AA9) -> WONOREJO | AT9: =IFERROR(K9,AB9) -> KALIWUNGU | AU9: =IFERROR(L9,AC9) -> TIDAK ADA | AV9: =IFERROR(M9,AD9) -> GOOD | AW9: =IFERROR(N9,AE9) -> 0 | AX9: =IFERROR(O9,AF9) -> TIDAK ADA
B10: P2 | C10: KENDAL | D10: 1411120251008411 | E10: PURWOTO | F10: Konsumen Aktif M 0 - 6 Lunas | G10: =VLOOKUP(D10,'DATABASE RO'!$B$3:$M$299,4,0) -> P408000001074 | H10: =VLOOKUP(D10,'DATABASE RO'!$B$3:$M$299,5,0) -> NO | I10: =VLOOKUP(D10,'DATABASE RO'!$B$3:$M$299,6,0) -> PERUM BTN BLOK B NO.8 RT 002 /RW 010, Langenharjo, Kendal, KAB-Kendal, 51314 | J10: =VLOOKUP(D10,'DATABASE RO'!$B$3:$M$299,7,0) -> LANGENHARJO | K10: =VLOOKUP(D10,'DATABASE RO'!$B$3:$M$299,8,0) -> KENDAL | L10: =VLOOKUP(D10,'DATABASE RO'!$B$3:$M$299,9,0) -> google.com/maps?z=12&t=m&q=loc:-6.584906+110.680564 | M10: =VLOOKUP(D10,'DATABASE RO'!$B$3:$M$299,10,0) -> EXCELLENT | O10: =VLOOKUP(D10,'DATABASE RO'!$B$3:$M$299,12,0) -> TIDAK ADA | S10: =B10 -> P2 | T10: =C10 -> KENDAL | U10: =D10 -> 1411120251008411 | V10: =E10 -> PURWOTO | X10: =VLOOKUP(V10,'DATABASE RO'!$C$3:$M$185,3,0) -> P408000001074 | Y10: =VLOOKUP(V10,'DATABASE RO'!$C$3:$M$185,4,0) -> NO | Z10: =VLOOKUP(V10,'DATABASE RO'!$C$3:$M$185,5,0) -> PERUM BTN BLOK B NO.8 RT 002 /RW 010, Langenharjo, Kendal, KAB-Kendal, 51314 | AA10: =VLOOKUP(V10,'DATABASE RO'!$C$3:$M$185,6,0) -> LANGENHARJO | AB10: =VLOOKUP(V10,'DATABASE RO'!$C$3:$M$185,7,0) -> KENDAL | AC10: =VLOOKUP(V10,'DATABASE RO'!$C$3:$M$185,8,0) -> google.com/maps?z=12&t=m&q=loc:-6.584906+110.680564 | AD10: =VLOOKUP(V10,'DATABASE RO'!$C$3:$M$185,9,0) -> EXCELLENT | AF10: =VLOOKUP(V10,'DATABASE RO'!$C$3:$M$185,11,0) -> TIDAK ADA | AK10: =B10 -> P2 | AL10: =C10 -> KENDAL | AM10: =D10 -> 1411120251008411 | AN10: =E10 -> PURWOTO | AO10: =F10 -> Konsumen Aktif M 0 - 6 Lunas | AP10: =IFERROR(G10,X10) -> P408000001074 | AQ10: =IFERROR(H10,Y10) -> NO | AR10: =IFERROR(I10,Z10) -> PERUM BTN BLOK B NO.8 RT 002 /RW 010, Langenharjo, Kendal, KAB-Kendal, 51314 | AS10: =IFERROR(J10,AA10) -> LANGENHARJO | AT10: =IFERROR(K10,AB10) -> KENDAL | AU10: =IFERROR(L10,AC10) -> google.com/maps?z=12&t=m&q=loc:-6.584906+110.680564 | AV10: =IFERROR(M10,AD10) -> EXCELLENT | AW10: =IFERROR(N10,AE10) -> 0 | AX10: =IFERROR(O10,AF10) -> TIDAK ADA
A11: VLOOKUP NAMA | B11: P2 | C11: KENDAL | D11: 1063120240104443 | E11: Satoto | F11: Konsumen Aktif M 0 - 6 Lunas | G11: =VLOOKUP(D11,'DATABASE RO'!$B$3:$M$299,4,0) -> #N/A | H11: =VLOOKUP(D11,'DATABASE RO'!$B$3:$M$299,5,0) -> #N/A | I11: =VLOOKUP(D11,'DATABASE RO'!$B$3:$M$299,6,0) -> #N/A | J11: =VLOOKUP(D11,'DATABASE RO'!$B$3:$M$299,7,0) -> #N/A | K11: =VLOOKUP(D11,'DATABASE RO'!$B$3:$M$299,8,0) -> #N/A | L11: =VLOOKUP(D11,'DATABASE RO'!$B$3:$M$299,9,0) -> #N/A | M11: =VLOOKUP(D11,'DATABASE RO'!$B$3:$M$299,10,0) -> #N/A | O11: =VLOOKUP(D11,'DATABASE RO'!$B$3:$M$299,12,0) -> #N/A | S11: =B11 -> P2 | T11: =C11 -> KENDAL | U11: =D11 -> 1063120240104443 | V11: =E11 -> Satoto | X11: =VLOOKUP(V11,'DATABASE RO'!$C$3:$M$185,3,0) -> #N/A | Y11: =VLOOKUP(V11,'DATABASE RO'!$C$3:$M$185,4,0) -> #N/A | Z11: =VLOOKUP(V11,'DATABASE RO'!$C$3:$M$185,5,0) -> #N/A | AA11: =VLOOKUP(V11,'DATABASE RO'!$C$3:$M$185,6,0) -> #N/A | AB11: =VLOOKUP(V11,'DATABASE RO'!$C$3:$M$185,7,0) -> #N/A | AC11: =VLOOKUP(V11,'DATABASE RO'!$C$3:$M$185,8,0) -> #N/A | AD11: =VLOOKUP(V11,'DATABASE RO'!$C$3:$M$185,9,0) -> #N/A | AF11: =VLOOKUP(V11,'DATABASE RO'!$C$3:$M$185,11,0) -> #N/A | AJ11: VLOOKUP NAMA | AK11: =B11 -> P2 | AL11: =C11 -> KENDAL | AM11: =D11 -> 1063120240104443 | AN11: =E11 -> Satoto | AO11: =F11 -> Konsumen Aktif M 0 - 6 Lunas | AP11: =IFERROR(G11,X11) -> #N/A | AQ11: =IFERROR(H11,Y11) -> #N/A | AR11: =IFERROR(I11,Z11) -> #N/A | AS11: =IFERROR(J11,AA11) -> #N/A | AT11: =IFERROR(K11,AB11) -> #N/A | AU11: =IFERROR(L11,AC11) -> #N/A | AV11: =IFERROR(M11,AD11) -> #N/A | AW11: =IFERROR(N11,AE11) -> 0 | AX11: =IFERROR(O11,AF11) -> #N/A
A12: VLOOKUP NAMA | B12: P2 | C12: KENDAL | D12: 1063120240304500 | E12: NURHAYATI | F12: Konsumen Aktif M 0 - 6 Lunas | G12: =VLOOKUP(D12,'DATABASE RO'!$B$3:$M$299,4,0) -> #N/A | H12: =VLOOKUP(D12,'DATABASE RO'!$B$3:$M$299,5,0) -> #N/A | I12: =VLOOKUP(D12,'DATABASE RO'!$B$3:$M$299,6,0) -> #N/A | J12: =VLOOKUP(D12,'DATABASE RO'!$B$3:$M$299,7,0) -> #N/A | K12: =VLOOKUP(D12,'DATABASE RO'!$B$3:$M$299,8,0) -> #N/A | L12: =VLOOKUP(D12,'DATABASE RO'!$B$3:$M$299,9,0) -> #N/A | M12: =VLOOKUP(D12,'DATABASE RO'!$B$3:$M$299,10,0) -> #N/A | O12: =VLOOKUP(D12,'DATABASE RO'!$B$3:$M$299,12,0) -> #N/A | S12: =B12 -> P2 | T12: =C12 -> KENDAL | U12: =D12 -> 1063120240304500 | V12: =E12 -> NURHAYATI | X12: =VLOOKUP(V12,'DATABASE RO'!$C$3:$M$185,3,0) -> P19002049199 | Y12: =VLOOKUP(V12,'DATABASE RO'!$C$3:$M$185,4,0) -> YES | Z12: =VLOOKUP(V12,'DATABASE RO'!$C$3:$M$185,5,0) -> PUCUNG KEREP DESA PESAREN RT 002 /RW 004, Pesaren, Sukorejo, KAB-Kendal, 51363 | AA12: =VLOOKUP(V12,'DATABASE RO'!$C$3:$M$185,6,0) -> Pesaren | AB12: =VLOOKUP(V12,'DATABASE RO'!$C$3:$M$185,7,0) -> Sukorejo | AC12: =VLOOKUP(V12,'DATABASE RO'!$C$3:$M$185,8,0) -> https://www.google.com/maps?z=12&t=m&q=loc:-7.139930+110.005402 | AD12: =VLOOKUP(V12,'DATABASE RO'!$C$3:$M$185,9,0) -> NORMAL | AF12: =VLOOKUP(V12,'DATABASE RO'!$C$3:$M$185,11,0) -> 0858 - 67822275 | AJ12: VLOOKUP NAMA | AK12: =B12 -> P2 | AL12: =C12 -> KENDAL | AM12: =D12 -> 1063120240304500 | AN12: =E12 -> NURHAYATI | AO12: =F12 -> Konsumen Aktif M 0 - 6 Lunas | AP12: =IFERROR(G12,X12) -> P19002049199 | AQ12: =IFERROR(H12,Y12) -> YES | AR12: =IFERROR(I12,Z12) -> PUCUNG KEREP DESA PESAREN RT 002 /RW 004, Pesaren, Sukorejo, KAB-Kendal, 51363 | AS12: =IFERROR(J12,AA12) -> Pesaren | AT12: =IFERROR(K12,AB12) -> Sukorejo | AU12: =IFERROR(L12,AC12) -> https://www.google.com/maps?z=12&t=m&q=loc:-7.139930+110.005402 | AV12: =IFERROR(M12,AD12) -> NORMAL | AW12: =IFERROR(N12,AE12) -> 0 | AX12: =IFERROR(O12,AF12) -> 0858 - 67822275
B13: P2 | C13: KENDAL | D13: 1063120240904763 | E13: Imam khoirudin | F13: Konsumen Aktif M 0 - 6 Lunas | G13: =VLOOKUP(D13,'DATABASE RO'!$B$3:$M$299,4,0) -> CUS063120211105567 | H13: =VLOOKUP(D13,'DATABASE RO'!$B$3:$M$299,5,0) -> #N/A | I13: =VLOOKUP(D13,'DATABASE RO'!$B$3:$M$299,6,0) -> BULUGEDE RT 001 /RW 002, Bulugede, Patebon, KAB-Kendal, 51351 | J13: =VLOOKUP(D13,'DATABASE RO'!$B$3:$M$299,7,0) -> Bulugede | K13: =VLOOKUP(D13,'DATABASE RO'!$B$3:$M$299,8,0) -> Patebon | L13: =VLOOKUP(D13,'DATABASE RO'!$B$3:$M$299,9,0) -> #N/A | M13: =VLOOKUP(D13,'DATABASE RO'!$B$3:$M$299,10,0) -> EXCELLENT | O13: =VLOOKUP(D13,'DATABASE RO'!$B$3:$M$299,12,0) -> 0895 - 630559311 | S13: =B13 -> P2 | T13: =C13 -> KENDAL | U13: =D13 -> 1063120240904763 | V13: =E13 -> Imam khoirudin | X13: =VLOOKUP(V13,'DATABASE RO'!$C$3:$M$185,3,0) -> CUS063120211105567 | Y13: =VLOOKUP(V13,'DATABASE RO'!$C$3:$M$185,4,0) -> #N/A | Z13: =VLOOKUP(V13,'DATABASE RO'!$C$3:$M$185,5,0) -> BULUGEDE RT 001 /RW 002, Bulugede, Patebon, KAB-Kendal, 51351 | AA13: =VLOOKUP(V13,'DATABASE RO'!$C$3:$M$185,6,0) -> Bulugede | AB13: =VLOOKUP(V13,'DATABASE RO'!$C$3:$M$185,7,0) -> Patebon | AC13: =VLOOKUP(V13,'DATABASE RO'!$C$3:$M$185,8,0) -> #N/A | AD13: =VLOOKUP(V13,'DATABASE RO'!$C$3:$M$185,9,0) -> EXCELLENT | AF13: =VLOOKUP(V13,'DATABASE RO'!$C$3:$M$185,11,0) -> 0895 - 630559311 | AK13: =B13 -> P2 | AL13: =C13 -> KENDAL | AM13: =D13 -> 1063120240904763 | AN13: =E13 -> Imam khoirudin | AO13: =F13 -> Konsumen Aktif M 0 - 6 Lunas | AP13: =IFERROR(G13,X13) -> CUS063120211105567 | AQ13: =IFERROR(H13,Y13) -> #N/A | AR13: =IFERROR(I13,Z13) -> BULUGEDE RT 001 /RW 002, Bulugede, Patebon, KAB-Kendal, 51351 | AS13: =IFERROR(J13,AA13) -> Bulugede | AT13: =IFERROR(K13,AB13) -> Patebon | AU13: =IFERROR(L13,AC13) -> #N/A | AV13: =IFERROR(M13,AD13) -> EXCELLENT | AW13: =IFERROR(N13,AE13) -> 0 | AX13: =IFERROR(O13,AF13) -> 0895 - 630559311
B14: P2 | C14: KENDAL | D14: 1063120241004777 | E14: ACHMAD CHAIRUL ANAM | F14: Konsumen Aktif M 0 - 6 Lunas | G14: =VLOOKUP(D14,'DATABASE RO'!$B$3:$M$299,4,0) -> CUS063120231107843 | H14: =VLOOKUP(D14,'DATABASE RO'!$B$3:$M$299,5,0) -> YES | I14: =VLOOKUP(D14,'DATABASE RO'!$B$3:$M$299,6,0) -> DK PONGOL SARI RT 005 /RW 002, Madugowongjati, Gringsing, KAB-Batang, 51281 | J14: =VLOOKUP(D14,'DATABASE RO'!$B$3:$M$299,7,0) -> Madugowongjati | K14: =VLOOKUP(D14,'DATABASE RO'!$B$3:$M$299,8,0) -> Gringsing | L14: =VLOOKUP(D14,'DATABASE RO'!$B$3:$M$299,9,0) -> https://www.google.com/maps/place/6%C2%B059'19.5%22S+109%C2%B059'08.9%22E/@-6.98875,109.9832371,17z/data=!3m1!4b1!4m4!3m3!8m2!3d-6.98875!4d109.985812?entry=ttu&g_ep=EgoyMDI2MDYyOS4wIKXMDSoASAFQAw%3D%3D | M14: =VLOOKUP(D14,'DATABASE RO'!$B$3:$M$299,10,0) -> EXCELLENT | O14: =VLOOKUP(D14,'DATABASE RO'!$B$3:$M$299,12,0) -> 0857 - 02254450 | S14: =B14 -> P2 | T14: =C14 -> KENDAL | U14: =D14 -> 1063120241004777 | V14: =E14 -> ACHMAD CHAIRUL ANAM | X14: =VLOOKUP(V14,'DATABASE RO'!$C$3:$M$185,3,0) -> CUS063120231107843 | Y14: =VLOOKUP(V14,'DATABASE RO'!$C$3:$M$185,4,0) -> YES | Z14: =VLOOKUP(V14,'DATABASE RO'!$C$3:$M$185,5,0) -> DK PONGOL SARI RT 005 /RW 002, Madugowongjati, Gringsing, KAB-Batang, 51281 | AA14: =VLOOKUP(V14,'DATABASE RO'!$C$3:$M$185,6,0) -> Madugowongjati | AB14: =VLOOKUP(V14,'DATABASE RO'!$C$3:$M$185,7,0) -> Gringsing | AC14: =VLOOKUP(V14,'DATABASE RO'!$C$3:$M$185,8,0) -> https://www.google.com/maps/place/6%C2%B059'19.5%22S+109%C2%B059'08.9%22E/@-6.98875,109.9832371,17z/data=!3m1!4b1!4m4!3m3!8m2!3d-6.98875!4d109.985812?entry=ttu&g_ep=EgoyMDI2MDYyOS4wIKXMDSoASAFQAw%3D%3D | AD14: =VLOOKUP(V14,'DATABASE RO'!$C$3:$M$185,9,0) -> EXCELLENT | AF14: =VLOOKUP(V14,'DATABASE RO'!$C$3:$M$185,11,0) -> 0857 - 02254450 | AK14: =B14 -> P2 | AL14: =C14 -> KENDAL | AM14: =D14 -> 1063120241004777 | AN14: =E14 -> ACHMAD CHAIRUL ANAM | AO14: =F14 -> Konsumen Aktif M 0 - 6 Lunas | AP14: =IFERROR(G14,X14) -> CUS063120231107843 | AQ14: =IFERROR(H14,Y14) -> YES | AR14: =IFERROR(I14,Z14) -> DK PONGOL SARI RT 005 /RW 002, Madugowongjati, Gringsing, KAB-Batang, 51281 | AS14: =IFERROR(J14,AA14) -> Madugowongjati | AT14: =IFERROR(K14,AB14) -> Gringsing | AU14: =IFERROR(L14,AC14) -> https://www.google.com/maps/place/6%C2%B059'19.5%22S+109%C2%B059'08.9%22E/@-6.98875,109.9832371,17z/data=!3m1!4b1!4m4!3m3!8m2!3d-6.98875!4d109.985812?entry=ttu&g_ep=EgoyMDI2MDYyOS4wIKXMDSoASAFQAw%3D%3D | AV14: =IFERROR(M14,AD14) -> EXCELLENT | AW14: =IFERROR(N14,AE14) -> 0 | AX14: =IFERROR(O14,AF14) -> 0857 - 02254450
B15: P2 | C15: KENDAL | D15: 1063120241004791 | E15: HERMANTO | F15: Konsumen Aktif M 0 - 6 Lunas | G15: =VLOOKUP(D15,'DATABASE RO'!$B$3:$M$299,4,0) -> P091A002037332 | H15: =VLOOKUP(D15,'DATABASE RO'!$B$3:$M$299,5,0) -> YES | I15: =VLOOKUP(D15,'DATABASE RO'!$B$3:$M$299,6,0) -> Ngasinan RT 009 /RW 003, Ngasinan, Weleri, KAB-Kendal, 51355 | J15: =VLOOKUP(D15,'DATABASE RO'!$B$3:$M$299,7,0) -> Ngasinan | K15: =VLOOKUP(D15,'DATABASE RO'!$B$3:$M$299,8,0) -> Weleri | L15: =VLOOKUP(D15,'DATABASE RO'!$B$3:$M$299,9,0) -> https://www.google.com/maps?z=12&t=m&q=loc:-6.971223+110.090367 | M15: =VLOOKUP(D15,'DATABASE RO'!$B$3:$M$299,10,0) -> EXCELLENT | O15: =VLOOKUP(D15,'DATABASE RO'!$B$3:$M$299,12,0) -> 0813 - 30005452 | S15: =B15 -> P2 | T15: =C15 -> KENDAL | U15: =D15 -> 1063120241004791 | V15: =E15 -> HERMANTO | X15: =VLOOKUP(V15,'DATABASE RO'!$C$3:$M$185,3,0) -> P091A002037332 | Y15: =VLOOKUP(V15,'DATABASE RO'!$C$3:$M$185,4,0) -> YES | Z15: =VLOOKUP(V15,'DATABASE RO'!$C$3:$M$185,5,0) -> Ngasinan RT 009 /RW 003, Ngasinan, Weleri, KAB-Kendal, 51355 | AA15: =VLOOKUP(V15,'DATABASE RO'!$C$3:$M$185,6,0) -> Ngasinan | AB15: =VLOOKUP(V15,'DATABASE RO'!$C$3:$M$185,7,0) -> Weleri | AC15: =VLOOKUP(V15,'DATABASE RO'!$C$3:$M$185,8,0) -> https://www.google.com/maps?z=12&t=m&q=loc:-6.971223+110.090367 | AD15: =VLOOKUP(V15,'DATABASE RO'!$C$3:$M$185,9,0) -> EXCELLENT | AF15: =VLOOKUP(V15,'DATABASE RO'!$C$3:$M$185,11,0) -> 0813 - 30005452 | AK15: =B15 -> P2 | AL15: =C15 -> KENDAL | AM15: =D15 -> 1063120241004791 | AN15: =E15 -> HERMANTO | AO15: =F15 -> Konsumen Aktif M 0 - 6 Lunas | AP15: =IFERROR(G15,X15) -> P091A002037332 | AQ15: =IFERROR(H15,Y15) -> YES | AR15: =IFERROR(I15,Z15) -> Ngasinan RT 009 /RW 003, Ngasinan, Weleri, KAB-Kendal, 51355 | AS15: =IFERROR(J15,AA15) -> Ngasinan | AT15: =IFERROR(K15,AB15) -> Weleri | AU15: =IFERROR(L15,AC15) -> https://www.google.com/maps?z=12&t=m&q=loc:-6.971223+110.090367 | AV15: =IFERROR(M15,AD15) -> EXCELLENT | AW15: =IFERROR(N15,AE15) -> 0 | AX15: =IFERROR(O15,AF15) -> 0813 - 30005452
B16: P2 | C16: KENDAL | D16: 1063120241004798 | E16: SITI MASROFAH | F16: Konsumen Aktif M 0 - 6 Lunas | G16: =VLOOKUP(D16,'DATABASE RO'!$B$3:$M$299,4,0) -> CUS063120241008307 | H16: =VLOOKUP(D16,'DATABASE RO'!$B$3:$M$299,5,0) -> YES | I16: =VLOOKUP(D16,'DATABASE RO'!$B$3:$M$299,6,0) -> DESA GEBANGANOM WETAN RT 006 /RW 001, Gebanganom Wetan, Kangkung, KAB-Kendal, 51353 | J16: =VLOOKUP(D16,'DATABASE RO'!$B$3:$M$299,7,0) -> Gebanganom Wetan | K16: =VLOOKUP(D16,'DATABASE RO'!$B$3:$M$299,8,0) -> Kangkung | L16: =VLOOKUP(D16,'DATABASE RO'!$B$3:$M$299,9,0) -> https://www.google.com/maps/place/6%C2%B056'20.0%22S+110%C2%B007'29.6%22E/@-6.938877,110.1223221,17z/data=!3m1!4b1!4m4!3m3!8m2!3d-6.938877!4d110.124897?entry=ttu&g_ep=EgoyMDI2MDcwOC4wIKXMDSoASAFQAw%3D%3D | M16: =VLOOKUP(D16,'DATABASE RO'!$B$3:$M$299,10,0) -> EXCELLENT | O16: =VLOOKUP(D16,'DATABASE RO'!$B$3:$M$299,12,0) -> 085520754148 | S16: =B16 -> P2 | T16: =C16 -> KENDAL | U16: =D16 -> 1063120241004798 | V16: =E16 -> SITI MASROFAH | X16: =VLOOKUP(V16,'DATABASE RO'!$C$3:$M$185,3,0) -> CUS063120241008307 | Y16: =VLOOKUP(V16,'DATABASE RO'!$C$3:$M$185,4,0) -> YES | Z16: =VLOOKUP(V16,'DATABASE RO'!$C$3:$M$185,5,0) -> DESA GEBANGANOM WETAN RT 006 /RW 001, Gebanganom Wetan, Kangkung, KAB-Kendal, 51353 | AA16: =VLOOKUP(V16,'DATABASE RO'!$C$3:$M$185,6,0) -> Gebanganom Wetan | AB16: =VLOOKUP(V16,'DATABASE RO'!$C$3:$M$185,7,0) -> Kangkung | AC16: =VLOOKUP(V16,'DATABASE RO'!$C$3:$M$185,8,0) -> https://www.google.com/maps/place/6%C2%B056'20.0%22S+110%C2%B007'29.6%22E/@-6.938877,110.1223221,17z/data=!3m1!4b1!4m4!3m3!8m2!3d-6.938877!4d110.124897?entry=ttu&g_ep=EgoyMDI2MDcwOC4wIKXMDSoASAFQAw%3D%3D | AD16: =VLOOKUP(V16,'DATABASE RO'!$C$3:$M$185,9,0) -> EXCELLENT | AF16: =VLOOKUP(V16,'DATABASE RO'!$C$3:$M$185,11,0) -> 085520754148 | AK16: =B16 -> P2 | AL16: =C16 -> KENDAL | AM16: =D16 -> 1063120241004798 | AN16: =E16 -> SITI MASROFAH | AO16: =F16 -> Konsumen Aktif M 0 - 6 Lunas | AP16: =IFERROR(G16,X16) -> CUS063120241008307 | AQ16: =IFERROR(H16,Y16) -> YES | AR16: =IFERROR(I16,Z16) -> DESA GEBANGANOM WETAN RT 006 /RW 001, Gebanganom Wetan, Kangkung, KAB-Kendal, 51353 | AS16: =IFERROR(J16,AA16) -> Gebanganom Wetan | AT16: =IFERROR(K16,AB16) -> Kangkung | AU16: =IFERROR(L16,AC16) -> https://www.google.com/maps/place/6%C2%B056'20.0%22S+110%C2%B007'29.6%22E/@-6.938877,110.1223221,17z/data=!3m1!4b1!4m4!3m3!8m2!3d-6.938877!4d110.124897?entry=ttu&g_ep=EgoyMDI2MDcwOC4wIKXMDSoASAFQAw%3D%3D | AV16: =IFERROR(M16,AD16) -> EXCELLENT | AW16: =IFERROR(N16,AE16) -> 0 | AX16: =IFERROR(O16,AF16) -> 085520754148
B17: P2 | C17: KENDAL | D17: 1063120241004807 | E17: ANNAS MARZUKI | F17: Konsumen Aktif M 0 - 6 Lunas | G17: =VLOOKUP(D17,'DATABASE RO'!$B$3:$M$299,4,0) -> P19002037152 | H17: =VLOOKUP(D17,'DATABASE RO'!$B$3:$M$299,5,0) -> YES | I17: =VLOOKUP(D17,'DATABASE RO'!$B$3:$M$299,6,0) -> DESA PUGUH RT 001/004 RT 01 /RW 04, Puguh, Pegandon, KAB-Kendal, 51357 | J17: =VLOOKUP(D17,'DATABASE RO'!$B$3:$M$299,7,0) -> Puguh | K17: =VLOOKUP(D17,'DATABASE RO'!$B$3:$M$299,8,0) -> Pegandon | L17: =VLOOKUP(D17,'DATABASE RO'!$B$3:$M$299,9,0) -> TIDAK ADA | M17: =VLOOKUP(D17,'DATABASE RO'!$B$3:$M$299,10,0) -> GOOD | O17: =VLOOKUP(D17,'DATABASE RO'!$B$3:$M$299,12,0) -> 0882 - 007565578 | S17: =B17 -> P2 | T17: =C17 -> KENDAL | U17: =D17 -> 1063120241004807 | V17: =E17 -> ANNAS MARZUKI | X17: =VLOOKUP(V17,'DATABASE RO'!$C$3:$M$185,3,0) -> P19002037152 | Y17: =VLOOKUP(V17,'DATABASE RO'!$C$3:$M$185,4,0) -> YES | Z17: =VLOOKUP(V17,'DATABASE RO'!$C$3:$M$185,5,0) -> DESA PUGUH RT 001/004 RT 01 /RW 04, Puguh, Pegandon, KAB-Kendal, 51357 | AA17: =VLOOKUP(V17,'DATABASE RO'!$C$3:$M$185,6,0) -> Puguh | AB17: =VLOOKUP(V17,'DATABASE RO'!$C$3:$M$185,7,0) -> Pegandon | AC17: =VLOOKUP(V17,'DATABASE RO'!$C$3:$M$185,8,0) -> TIDAK ADA | AD17: =VLOOKUP(V17,'DATABASE RO'!$C$3:$M$185,9,0) -> GOOD | AF17: =VLOOKUP(V17,'DATABASE RO'!$C$3:$M$185,11,0) -> 0882 - 007565578 | AK17: =B17 -> P2 | AL17: =C17 -> KENDAL | AM17: =D17 -> 1063120241004807 | AN17: =E17 -> ANNAS MARZUKI | AO17: =F17 -> Konsumen Aktif M 0 - 6 Lunas | AP17: =IFERROR(G17,X17) -> P19002037152 | AQ17: =IFERROR(H17,Y17) -> YES | AR17: =IFERROR(I17,Z17) -> DESA PUGUH RT 001/004 RT 01 /RW 04, Puguh, Pegandon, KAB-Kendal, 51357 | AS17: =IFERROR(J17,AA17) -> Puguh | AT17: =IFERROR(K17,AB17) -> Pegandon | AU17: =IFERROR(L17,AC17) -> TIDAK ADA | AV17: =IFERROR(M17,AD17) -> GOOD | AW17: =IFERROR(N17,AE17) -> 0 | AX17: =IFERROR(O17,AF17) -> 0882 - 007565578
B18: P2 | C18: KENDAL | D18: 1063120241104840 | E18: CAHYA KARDININGSIH | F18: Konsumen Aktif M 0 - 6 Lunas | G18: =VLOOKUP(D18,'DATABASE RO'!$B$3:$M$299,4,0) -> CUS063120221106822 | H18: =VLOOKUP(D18,'DATABASE RO'!$B$3:$M$299,5,0) -> YES | I18: =VLOOKUP(D18,'DATABASE RO'!$B$3:$M$299,6,0) -> TEMPEL RT 010 /RW 003, Bumiayu, Weleri, KAB-Kendal, 51355 | J18: =VLOOKUP(D18,'DATABASE RO'!$B$3:$M$299,7,0) -> Bumiayu | K18: =VLOOKUP(D18,'DATABASE RO'!$B$3:$M$299,8,0) -> Weleri | L18: =VLOOKUP(D18,'DATABASE RO'!$B$3:$M$299,9,0) -> https://www.google.com/maps?z=12&t=m&q=loc:-6.981893+110.073458 | M18: =VLOOKUP(D18,'DATABASE RO'!$B$3:$M$299,10,0) -> EXCELLENT | O18: =VLOOKUP(D18,'DATABASE RO'!$B$3:$M$299,12,0) -> 083121132031 | S18: =B18 -> P2 | T18: =C18 -> KENDAL | U18: =D18 -> 1063120241104840 | V18: =E18 -> CAHYA KARDININGSIH | X18: =VLOOKUP(V18,'DATABASE RO'!$C$3:$M$185,3,0) -> CUS063120221106822 | Y18: =VLOOKUP(V18,'DATABASE RO'!$C$3:$M$185,4,0) -> YES | Z18: =VLOOKUP(V18,'DATABASE RO'!$C$3:$M$185,5,0) -> TEMPEL RT 010 /RW 003, Bumiayu, Weleri, KAB-Kendal, 51355 | AA18: =VLOOKUP(V18,'DATABASE RO'!$C$3:$M$185,6,0) -> Bumiayu | AB18: =VLOOKUP(V18,'DATABASE RO'!$C$3:$M$185,7,0) -> Weleri | AC18: =VLOOKUP(V18,'DATABASE RO'!$C$3:$M$185,8,0) -> https://www.google.com/maps?z=12&t=m&q=loc:-6.981893+110.073458 | AD18: =VLOOKUP(V18,'DATABASE RO'!$C$3:$M$185,9,0) -> EXCELLENT | AF18: =VLOOKUP(V18,'DATABASE RO'!$C$3:$M$185,11,0) -> 083121132031 | AK18: =B18 -> P2 | AL18: =C18 -> KENDAL | AM18: =D18 -> 1063120241104840 | AN18: =E18 -> CAHYA KARDININGSIH | AO18: =F18 -> Konsumen Aktif M 0 - 6 Lunas | AP18: =IFERROR(G18,X18) -> CUS063120221106822 | AQ18: =IFERROR(H18,Y18) -> YES | AR18: =IFERROR(I18,Z18) -> TEMPEL RT 010 /RW 003, Bumiayu, Weleri, KAB-Kendal, 51355 | AS18: =IFERROR(J18,AA18) -> Bumiayu | AT18: =IFERROR(K18,AB18) -> Weleri | AU18: =IFERROR(L18,AC18) -> https://www.google.com/maps?z=12&t=m&q=loc:-6.981893+110.073458 | AV18: =IFERROR(M18,AD18) -> EXCELLENT | AW18: =IFERROR(N18,AE18) -> 0 | AX18: =IFERROR(O18,AF18) -> 083121132031
B19: P2 | C19: KENDAL | D19: 1063120241204874 | E19: Riyantik | F19: Konsumen Aktif M 0 - 6 Lunas | G19: =VLOOKUP(D19,'DATABASE RO'!$B$3:$M$299,4,0) -> CUS063120221006705 | H19: =VLOOKUP(D19,'DATABASE RO'!$B$3:$M$299,5,0) -> YES | I19: =VLOOKUP(D19,'DATABASE RO'!$B$3:$M$299,6,0) -> SAMBONGSARI RT 003 /RW 001, Sambongsari, Weleri, KAB-Kendal, 51355 | J19: =VLOOKUP(D19,'DATABASE RO'!$B$3:$M$299,7,0) -> Sambongsari | K19: =VLOOKUP(D19,'DATABASE RO'!$B$3:$M$299,8,0) -> Weleri | L19: =VLOOKUP(D19,'DATABASE RO'!$B$3:$M$299,9,0) -> google.com/maps?z=12&t=m&q=loc:-6.972847+110.059785 | M19: =VLOOKUP(D19,'DATABASE RO'!$B$3:$M$299,10,0) -> NORMAL | O19: =VLOOKUP(D19,'DATABASE RO'!$B$3:$M$299,12,0) -> 08988383160 | S19: =B19 -> P2 | T19: =C19 -> KENDAL | U19: =D19 -> 1063120241204874 | V19: =E19 -> Riyantik | X19: =VLOOKUP(V19,'DATABASE RO'!$C$3:$M$185,3,0) -> CUS063120221006705 | Y19: =VLOOKUP(V19,'DATABASE RO'!$C$3:$M$185,4,0) -> YES | Z19: =VLOOKUP(V19,'DATABASE RO'!$C$3:$M$185,5,0) -> SAMBONGSARI RT 003 /RW 001, Sambongsari, Weleri, KAB-Kendal, 51355 | AA19: =VLOOKUP(V19,'DATABASE RO'!$C$3:$M$185,6,0) -> Sambongsari | AB19: =VLOOKUP(V19,'DATABASE RO'!$C$3:$M$185,7,0) -> Weleri | AC19: =VLOOKUP(V19,'DATABASE RO'!$C$3:$M$185,8,0) -> google.com/maps?z=12&t=m&q=loc:-6.972847+110.059785 | AD19: =VLOOKUP(V19,'DATABASE RO'!$C$3:$M$185,9,0) -> NORMAL | AF19: =VLOOKUP(V19,'DATABASE RO'!$C$3:$M$185,11,0) -> 08988383160 | AK19: =B19 -> P2 | AL19: =C19 -> KENDAL | AM19: =D19 -> 1063120241204874 | AN19: =E19 -> Riyantik | AO19: =F19 -> Konsumen Aktif M 0 - 6 Lunas | AP19: =IFERROR(G19,X19) -> CUS063120221006705 | AQ19: =IFERROR(H19,Y19) -> YES | AR19: =IFERROR(I19,Z19) -> SAMBONGSARI RT 003 /RW 001, Sambongsari, Weleri, KAB-Kendal, 51355 | AS19: =IFERROR(J19,AA19) -> Sambongsari | AT19: =IFERROR(K19,AB19) -> Weleri | AU19: =IFERROR(L19,AC19) -> google.com/maps?z=12&t=m&q=loc:-6.972847+110.059785 | AV19: =IFERROR(M19,AD19) -> NORMAL | AW19: =IFERROR(N19,AE19) -> 0 | AX19: =IFERROR(O19,AF19) -> 08988383160
B20: P2 | C20: KENDAL | D20: 1063120250104885 | E20: Andy Purnomo aji | F20: Konsumen Aktif M 0 - 6 Lunas | G20: =VLOOKUP(D20,'DATABASE RO'!$B$3:$M$299,4,0) -> CUS063120230307314 | H20: =VLOOKUP(D20,'DATABASE RO'!$B$3:$M$299,5,0) -> YES | I20: =VLOOKUP(D20,'DATABASE RO'!$B$3:$M$299,6,0) -> Langgengsari RT 005 /RW 002, Plantaran, Kaliwungu Selatan, KAB-Kendal, 51372 | J20: =VLOOKUP(D20,'DATABASE RO'!$B$3:$M$299,7,0) -> Plantaran | K20: =VLOOKUP(D20,'DATABASE RO'!$B$3:$M$299,8,0) -> Kaliwungu Selatan | L20: =VLOOKUP(D20,'DATABASE RO'!$B$3:$M$299,9,0) -> https://www.google.com/maps/place/6%C2%B057'59.5%22S+110%C2%B014'47.6%22E/@-6.966538,110.2439671,17z/data=!3m1!4b1!4m4!3m3!8m2!3d-6.966538!4d110.246542?entry=ttu&g_ep=EgoyMDI2MDYyOS4wIKXMDSoASAFQAw%3D%3D | M20: =VLOOKUP(D20,'DATABASE RO'!$B$3:$M$299,10,0) -> NORMAL | O20: =VLOOKUP(D20,'DATABASE RO'!$B$3:$M$299,12,0) -> 085713645032 | S20: =B20 -> P2 | T20: =C20 -> KENDAL | U20: =D20 -> 1063120250104885 | V20: =E20 -> Andy Purnomo aji | X20: =VLOOKUP(V20,'DATABASE RO'!$C$3:$M$185,3,0) -> CUS063120230307314 | Y20: =VLOOKUP(V20,'DATABASE RO'!$C$3:$M$185,4,0) -> YES | Z20: =VLOOKUP(V20,'DATABASE RO'!$C$3:$M$185,5,0) -> Langgengsari RT 005 /RW 002, Plantaran, Kaliwungu Selatan, KAB-Kendal, 51372 | AA20: =VLOOKUP(V20,'DATABASE RO'!$C$3:$M$185,6,0) -> Plantaran | AB20: =VLOOKUP(V20,'DATABASE RO'!$C$3:$M$185,7,0) -> Kaliwungu Selatan | AC20: =VLOOKUP(V20,'DATABASE RO'!$C$3:$M$185,8,0) -> https://www.google.com/maps/place/6%C2%B057'59.5%22S+110%C2%B014'47.6%22E/@-6.966538,110.2439671,17z/data=!3m1!4b1!4m4!3m3!8m2!3d-6.966538!4d110.246542?entry=ttu&g_ep=EgoyMDI2MDYyOS4wIKXMDSoASAFQAw%3D%3D | AD20: =VLOOKUP(V20,'DATABASE RO'!$C$3:$M$185,9,0) -> NORMAL | AF20: =VLOOKUP(V20,'DATABASE RO'!$C$3:$M$185,11,0) -> 085713645032 | AK20: =B20 -> P2 | AL20: =C20 -> KENDAL | AM20: =D20 -> 1063120250104885 | AN20: =E20 -> Andy Purnomo aji | AO20: =F20 -> Konsumen Aktif M 0 - 6 Lunas | AP20: =IFERROR(G20,X20) -> CUS063120230307314 | AQ20: =IFERROR(H20,Y20) -> YES | AR20: =IFERROR(I20,Z20) -> Langgengsari RT 005 /RW 002, Plantaran, Kaliwungu Selatan, KAB-Kendal, 51372 | AS20: =IFERROR(J20,AA20) -> Plantaran | AT20: =IFERROR(K20,AB20) -> Kaliwungu Selatan | AU20: =IFERROR(L20,AC20) -> https://www.google.com/maps/place/6%C2%B057'59.5%22S+110%C2%B014'47.6%22E/@-6.966538,110.2439671,17z/data=!3m1!4b1!4m4!3m3!8m2!3d-6.966538!4d110.246542?entry=ttu&g_ep=EgoyMDI2MDYyOS4wIKXMDSoASAFQAw%3D%3D | AV20: =IFERROR(M20,AD20) -> NORMAL | AW20: =IFERROR(N20,AE20) -> 0 | AX20: =IFERROR(O20,AF20) -> 085713645032
B21: P2 | C21: KENDAL | D21: 1063120250104886 | E21: AISI ULFA LUTHFIANA | F21: Konsumen Aktif M 0 - 6 Lunas | G21: =VLOOKUP(D21,'DATABASE RO'!$B$3:$M$299,4,0) -> CUS063120240408019 | H21: =VLOOKUP(D21,'DATABASE RO'!$B$3:$M$299,5,0) -> YES | I21: =VLOOKUP(D21,'DATABASE RO'!$B$3:$M$299,6,0) -> KEBON ANOM RT 005 /RW 006, Kebongembong, Pagerruyung, KAB-Kendal, 51361 | J21: =VLOOKUP(D21,'DATABASE RO'!$B$3:$M$299,7,0) -> Kebongembong | K21: =VLOOKUP(D21,'DATABASE RO'!$B$3:$M$299,8,0) -> Pagerruyung | L21: =VLOOKUP(D21,'DATABASE RO'!$B$3:$M$299,9,0) -> https://www.google.com/maps/place/7%C2%B001'29.2%22S+110%C2%B001'10.2%22E/@-7.02477,110.0169101,17z/data=!3m1!4b1!4m4!3m3!8m2!3d-7.02477!4d110.019485?entry=ttu&g_ep=EgoyMDI2MDYyOS4wIKXMDSoASAFQAw%3D%3D | M21: =VLOOKUP(D21,'DATABASE RO'!$B$3:$M$299,10,0) -> EXCELLENT | O21: =VLOOKUP(D21,'DATABASE RO'!$B$3:$M$299,12,0) -> 081285997827 | S21: =B21 -> P2 | T21: =C21 -> KENDAL | U21: =D21 -> 1063120250104886 | V21: =E21 -> AISI ULFA LUTHFIANA | X21: =VLOOKUP(V21,'DATABASE RO'!$C$3:$M$185,3,0) -> CUS063120240408019 | Y21: =VLOOKUP(V21,'DATABASE RO'!$C$3:$M$185,4,0) -> YES | Z21: =VLOOKUP(V21,'DATABASE RO'!$C$3:$M$185,5,0) -> KEBON ANOM RT 005 /RW 006, Kebongembong, Pagerruyung, KAB-Kendal, 51361 | AA21: =VLOOKUP(V21,'DATABASE RO'!$C$3:$M$185,6,0) -> Kebongembong | AB21: =VLOOKUP(V21,'DATABASE RO'!$C$3:$M$185,7,0) -> Pagerruyung | AC21: =VLOOKUP(V21,'DATABASE RO'!$C$3:$M$185,8,0) -> https://www.google.com/maps/place/7%C2%B001'29.2%22S+110%C2%B001'10.2%22E/@-7.02477,110.0169101,17z/data=!3m1!4b1!4m4!3m3!8m2!3d-7.02477!4d110.019485?entry=ttu&g_ep=EgoyMDI2MDYyOS4wIKXMDSoASAFQAw%3D%3D | AD21: =VLOOKUP(V21,'DATABASE RO'!$C$3:$M$185,9,0) -> EXCELLENT | AF21: =VLOOKUP(V21,'DATABASE RO'!$C$3:$M$185,11,0) -> 081285997827 | AK21: =B21 -> P2 | AL21: =C21 -> KENDAL | AM21: =D21 -> 1063120250104886 | AN21: =E21 -> AISI ULFA LUTHFIANA | AO21: =F21 -> Konsumen Aktif M 0 - 6 Lunas | AP21: =IFERROR(G21,X21) -> CUS063120240408019 | AQ21: =IFERROR(H21,Y21) -> YES | AR21: =IFERROR(I21,Z21) -> KEBON ANOM RT 005 /RW 006, Kebongembong, Pagerruyung, KAB-Kendal, 51361 | AS21: =IFERROR(J21,AA21) -> Kebongembong | AT21: =IFERROR(K21,AB21) -> Pagerruyung | AU21: =IFERROR(L21,AC21) -> https://www.google.com/maps/place/7%C2%B001'29.2%22S+110%C2%B001'10.2%22E/@-7.02477,110.0169101,17z/data=!3m1!4b1!4m4!3m3!8m2!3d-7.02477!4d110.019485?entry=ttu&g_ep=EgoyMDI2MDYyOS4wIKXMDSoASAFQAw%3D%3D | AV21: =IFERROR(M21,AD21) -> EXCELLENT | AW21: =IFERROR(N21,AE21) -> 0 | AX21: =IFERROR(O21,AF21) -> 081285997827
B22: P2 | C22: KENDAL | D22: 1063120250104897 | E22: MUHLISIN | F22: Konsumen Aktif M 0 - 6 Lunas | G22: =VLOOKUP(D22,'DATABASE RO'!$B$3:$M$299,4,0) -> CUS063120190701682 | H22: =VLOOKUP(D22,'DATABASE RO'!$B$3:$M$299,5,0) -> YES | I22: =VLOOKUP(D22,'DATABASE RO'!$B$3:$M$299,6,0) -> CEPOKOMULYO RT 003 /RW 005, Cepokomulyo, Gemuh, KAB-Kendal, 51356 | J22: =VLOOKUP(D22,'DATABASE RO'!$B$3:$M$299,7,0) -> Cepokomulyo | K22: =VLOOKUP(D22,'DATABASE RO'!$B$3:$M$299,8,0) -> Gemuh | L22: =VLOOKUP(D22,'DATABASE RO'!$B$3:$M$299,9,0) -> google.com/maps?z=12&t=m&q=loc:-6.992719+110.128260 | M22: =VLOOKUP(D22,'DATABASE RO'!$B$3:$M$299,10,0) -> EXCELLENT | O22: =VLOOKUP(D22,'DATABASE RO'!$B$3:$M$299,12,0) -> 082128848247 | S22: =B22 -> P2 | T22: =C22 -> KENDAL | U22: =D22 -> 1063120250104897 | V22: =E22 -> MUHLISIN | X22: =VLOOKUP(V22,'DATABASE RO'!$C$3:$M$185,3,0) -> CUS063120190701682 | Y22: =VLOOKUP(V22,'DATABASE RO'!$C$3:$M$185,4,0) -> YES | Z22: =VLOOKUP(V22,'DATABASE RO'!$C$3:$M$185,5,0) -> CEPOKOMULYO RT 003 /RW 005, Cepokomulyo, Gemuh, KAB-Kendal, 51356 | AA22: =VLOOKUP(V22,'DATABASE RO'!$C$3:$M$185,6,0) -> Cepokomulyo | AB22: =VLOOKUP(V22,'DATABASE RO'!$C$3:$M$185,7,0) -> Gemuh | AC22: =VLOOKUP(V22,'DATABASE RO'!$C$3:$M$185,8,0) -> google.com/maps?z=12&t=m&q=loc:-6.992719+110.128260 | AD22: =VLOOKUP(V22,'DATABASE RO'!$C$3:$M$185,9,0) -> EXCELLENT | AF22: =VLOOKUP(V22,'DATABASE RO'!$C$3:$M$185,11,0) -> 082128848247 | AK22: =B22 -> P2 | AL22: =C22 -> KENDAL | AM22: =D22 -> 1063120250104897 | AN22: =E22 -> MUHLISIN | AO22: =F22 -> Konsumen Aktif M 0 - 6 Lunas | AP22: =IFERROR(G22,X22) -> CUS063120190701682 | AQ22: =IFERROR(H22,Y22) -> YES | AR22: =IFERROR(I22,Z22) -> CEPOKOMULYO RT 003 /RW 005, Cepokomulyo, Gemuh, KAB-Kendal, 51356 | AS22: =IFERROR(J22,AA22) -> Cepokomulyo | AT22: =IFERROR(K22,AB22) -> Gemuh | AU22: =IFERROR(L22,AC22) -> google.com/maps?z=12&t=m&q=loc:-6.992719+110.128260 | AV22: =IFERROR(M22,AD22) -> EXCELLENT | AW22: =IFERROR(N22,AE22) -> 0 | AX22: =IFERROR(O22,AF22) -> 082128848247
A23: VLOOKUP NAMA | B23: P2 | C23: KENDAL | D23: 1063120250104901 | E23: PURNOMOSIDI | F23: Konsumen Aktif M 0 - 6 Lunas | G23: =VLOOKUP(D23,'DATABASE RO'!$B$3:$M$299,4,0) -> #N/A | H23: =VLOOKUP(D23,'DATABASE RO'!$B$3:$M$299,5,0) -> #N/A | I23: =VLOOKUP(D23,'DATABASE RO'!$B$3:$M$299,6,0) -> #N/A | J23: =VLOOKUP(D23,'DATABASE RO'!$B$3:$M$299,7,0) -> #N/A | K23: =VLOOKUP(D23,'DATABASE RO'!$B$3:$M$299,8,0) -> #N/A | L23: =VLOOKUP(D23,'DATABASE RO'!$B$3:$M$299,9,0) -> #N/A | M23: =VLOOKUP(D23,'DATABASE RO'!$B$3:$M$299,10,0) -> #N/A | O23: =VLOOKUP(D23,'DATABASE RO'!$B$3:$M$299,12,0) -> #N/A | S23: =B23 -> P2 | T23: =C23 -> KENDAL | U23: =D23 -> 1063120250104901 | V23: =E23 -> PURNOMOSIDI | X23: =VLOOKUP(V23,'DATABASE RO'!$C$3:$M$185,3,0) -> P19002058659 | Y23: =VLOOKUP(V23,'DATABASE RO'!$C$3:$M$185,4,0) -> YES | Z23: =VLOOKUP(V23,'DATABASE RO'!$C$3:$M$185,5,0) -> PERUM GRAHA RAYA NO. 265 RT 008 /RW 010, Sarirejo, Kaliwungu, KAB-Kendal, 51372 | AA23: =VLOOKUP(V23,'DATABASE RO'!$C$3:$M$185,6,0) -> Sarirejo | AB23: =VLOOKUP(V23,'DATABASE RO'!$C$3:$M$185,7,0) -> Kaliwungu | AC23: =VLOOKUP(V23,'DATABASE RO'!$C$3:$M$185,8,0) -> http://maps.google.com/maps?z=12&t=m&q=loc:-6.942429+110.253472 | AD23: =VLOOKUP(V23,'DATABASE RO'!$C$3:$M$185,9,0) -> EXCELLENT | AF23: =VLOOKUP(V23,'DATABASE RO'!$C$3:$M$185,11,0) -> 0812 - 25579340 | AJ23: VLOOKUP NAMA | AK23: =B23 -> P2 | AL23: =C23 -> KENDAL | AM23: =D23 -> 1063120250104901 | AN23: =E23 -> PURNOMOSIDI | AO23: =F23 -> Konsumen Aktif M 0 - 6 Lunas | AP23: =IFERROR(G23,X23) -> P19002058659 | AQ23: =IFERROR(H23,Y23) -> YES | AR23: =IFERROR(I23,Z23) -> PERUM GRAHA RAYA NO. 265 RT 008 /RW 010, Sarirejo, Kaliwungu, KAB-Kendal, 51372 | AS23: =IFERROR(J23,AA23) -> Sarirejo | AT23: =IFERROR(K23,AB23) -> Kaliwungu | AU23: =IFERROR(L23,AC23) -> http://maps.google.com/maps?z=12&t=m&q=loc:-6.942429+110.253472 | AV23: =IFERROR(M23,AD23) -> EXCELLENT | AW23: =IFERROR(N23,AE23) -> 0 | AX23: =IFERROR(O23,AF23) -> 0812 - 25579340
A24: VLOOKUP NAMA | B24: P2 | C24: KENDAL | D24: 1063120250104907 | E24: TITIN GIARSI | F24: Konsumen Aktif M 0 - 6 Lunas | G24: =VLOOKUP(D24,'DATABASE RO'!$B$3:$M$299,4,0) -> #N/A | H24: =VLOOKUP(D24,'DATABASE RO'!$B$3:$M$299,5,0) -> #N/A | I24: =VLOOKUP(D24,'DATABASE RO'!$B$3:$M$299,6,0) -> #N/A | J24: =VLOOKUP(D24,'DATABASE RO'!$B$3:$M$299,7,0) -> #N/A | K24: =VLOOKUP(D24,'DATABASE RO'!$B$3:$M$299,8,0) -> #N/A | L24: =VLOOKUP(D24,'DATABASE RO'!$B$3:$M$299,9,0) -> #N/A | M24: =VLOOKUP(D24,'DATABASE RO'!$B$3:$M$299,10,0) -> #N/A | O24: =VLOOKUP(D24,'DATABASE RO'!$B$3:$M$299,12,0) -> #N/A | S24: =B24 -> P2 | T24: =C24 -> KENDAL | U24: =D24 -> 1063120250104907 | V24: =E24 -> TITIN GIARSI | X24: =VLOOKUP(V24,'DATABASE RO'!$C$3:$M$185,3,0) -> #N/A | Y24: =VLOOKUP(V24,'DATABASE RO'!$C$3:$M$185,4,0) -> #N/A | Z24: =VLOOKUP(V24,'DATABASE RO'!$C$3:$M$185,5,0) -> #N/A | AA24: =VLOOKUP(V24,'DATABASE RO'!$C$3:$M$185,6,0) -> #N/A | AB24: =VLOOKUP(V24,'DATABASE RO'!$C$3:$M$185,7,0) -> #N/A | AC24: =VLOOKUP(V24,'DATABASE RO'!$C$3:$M$185,8,0) -> #N/A | AD24: =VLOOKUP(V24,'DATABASE RO'!$C$3:$M$185,9,0) -> #N/A | AF24: =VLOOKUP(V24,'DATABASE RO'!$C$3:$M$185,11,0) -> #N/A | AJ24: VLOOKUP NAMA | AK24: =B24 -> P2 | AL24: =C24 -> KENDAL | AM24: =D24 -> 1063120250104907 | AN24: =E24 -> TITIN GIARSI | AO24: =F24 -> Konsumen Aktif M 0 - 6 Lunas | AP24: =IFERROR(G24,X24) -> #N/A | AQ24: =IFERROR(H24,Y24) -> #N/A | AR24: =IFERROR(I24,Z24) -> #N/A | AS24: =IFERROR(J24,AA24) -> #N/A | AT24: =IFERROR(K24,AB24) -> #N/A | AU24: =IFERROR(L24,AC24) -> #N/A | AV24: =IFERROR(M24,AD24) -> #N/A | AW24: =IFERROR(N24,AE24) -> 0 | AX24: =IFERROR(O24,AF24) -> #N/A
A25: VLOOKUP NAMA | B25: P2 | C25: KENDAL | D25: 1063120250204915 | E25: SITI ROHMAH | F25: Konsumen Aktif M 0 - 6 Lunas | G25: =VLOOKUP(D25,'DATABASE RO'!$B$3:$M$299,4,0) -> #N/A | H25: =VLOOKUP(D25,'DATABASE RO'!$B$3:$M$299,5,0) -> #N/A | I25: =VLOOKUP(D25,'DATABASE RO'!$B$3:$M$299,6,0) -> #N/A | J25: =VLOOKUP(D25,'DATABASE RO'!$B$3:$M$299,7,0) -> #N/A | K25: =VLOOKUP(D25,'DATABASE RO'!$B$3:$M$299,8,0) -> #N/A | L25: =VLOOKUP(D25,'DATABASE RO'!$B$3:$M$299,9,0) -> #N/A | M25: =VLOOKUP(D25,'DATABASE RO'!$B$3:$M$299,10,0) -> #N/A | O25: =VLOOKUP(D25,'DATABASE RO'!$B$3:$M$299,12,0) -> #N/A | S25: =B25 -> P2 | T25: =C25 -> KENDAL | U25: =D25 -> 1063120250204915 | V25: =E25 -> SITI ROHMAH | X25: =VLOOKUP(V25,'DATABASE RO'!$C$3:$M$185,3,0) -> #N/A | Y25: =VLOOKUP(V25,'DATABASE RO'!$C$3:$M$185,4,0) -> #N/A | Z25: =VLOOKUP(V25,'DATABASE RO'!$C$3:$M$185,5,0) -> #N/A | AA25: =VLOOKUP(V25,'DATABASE RO'!$C$3:$M$185,6,0) -> #N/A | AB25: =VLOOKUP(V25,'DATABASE RO'!$C$3:$M$185,7,0) -> #N/A | AC25: =VLOOKUP(V25,'DATABASE RO'!$C$3:$M$185,8,0) -> #N/A | AD25: =VLOOKUP(V25,'DATABASE RO'!$C$3:$M$185,9,0) -> #N/A | AF25: =VLOOKUP(V25,'DATABASE RO'!$C$3:$M$185,11,0) -> #N/A | AJ25: VLOOKUP NAMA | AK25: =B25 -> P2 | AL25: =C25 -> KENDAL | AM25: =D25 -> 1063120250204915 | AN25: =E25 -> SITI ROHMAH | AO25: =F25 -> Konsumen Aktif M 0 - 6 Lunas | AP25: =IFERROR(G25,X25) -> #N/A | AQ25: =IFERROR(H25,Y25) -> #N/A | AR25: =IFERROR(I25,Z25) -> #N/A | AS25: =IFERROR(J25,AA25) -> #N/A | AT25: =IFERROR(K25,AB25) -> #N/A | AU25: =IFERROR(L25,AC25) -> #N/A | AV25: =IFERROR(M25,AD25) -> #N/A | AW25: =IFERROR(N25,AE25) -> 0 | AX25: =IFERROR(O25,AF25) -> #N/A
A26: VLOOKUP NAMA | B26: P2 | C26: KENDAL | D26: 1063120250204922 | E26: AHMAD SAIFUL | F26: Konsumen Aktif M 0 - 6 Lunas | G26: =VLOOKUP(D26,'DATABASE RO'!$B$3:$M$299,4,0) -> #N/A | H26: =VLOOKUP(D26,'DATABASE RO'!$B$3:$M$299,5,0) -> #N/A | I26: =VLOOKUP(D26,'DATABASE RO'!$B$3:$M$299,6,0) -> #N/A | J26: =VLOOKUP(D26,'DATABASE RO'!$B$3:$M$299,7,0) -> #N/A | K26: =VLOOKUP(D26,'DATABASE RO'!$B$3:$M$299,8,0) -> #N/A | L26: =VLOOKUP(D26,'DATABASE RO'!$B$3:$M$299,9,0) -> #N/A | M26: =VLOOKUP(D26,'DATABASE RO'!$B$3:$M$299,10,0) -> #N/A | O26: =VLOOKUP(D26,'DATABASE RO'!$B$3:$M$299,12,0) -> #N/A | S26: =B26 -> P2 | T26: =C26 -> KENDAL | U26: =D26 -> 1063120250204922 | V26: =E26 -> AHMAD SAIFUL | X26: =VLOOKUP(V26,'DATABASE RO'!$C$3:$M$185,3,0) -> #N/A | Y26: =VLOOKUP(V26,'DATABASE RO'!$C$3:$M$185,4,0) -> #N/A | Z26: =VLOOKUP(V26,'DATABASE RO'!$C$3:$M$185,5,0) -> #N/A | AA26: =VLOOKUP(V26,'DATABASE RO'!$C$3:$M$185,6,0) -> #N/A | AB26: =VLOOKUP(V26,'DATABASE RO'!$C$3:$M$185,7,0) -> #N/A | AC26: =VLOOKUP(V26,'DATABASE RO'!$C$3:$M$185,8,0) -> #N/A | AD26: =VLOOKUP(V26,'DATABASE RO'!$C$3:$M$185,9,0) -> #N/A | AF26: =VLOOKUP(V26,'DATABASE RO'!$C$3:$M$185,11,0) -> #N/A | AJ26: VLOOKUP NAMA | AK26: =B26 -> P2 | AL26: =C26 -> KENDAL | AM26: =D26 -> 1063120250204922 | AN26: =E26 -> AHMAD SAIFUL | AO26: =F26 -> Konsumen Aktif M 0 - 6 Lunas | AP26: =IFERROR(G26,X26) -> #N/A | AQ26: =IFERROR(H26,Y26) -> #N/A | AR26: =IFERROR(I26,Z26) -> #N/A | AS26: =IFERROR(J26,AA26) -> #N/A | AT26: =IFERROR(K26,AB26) -> #N/A | AU26: =IFERROR(L26,AC26) -> #N/A | AV26: =IFERROR(M26,AD26) -> #N/A | AW26: =IFERROR(N26,AE26) -> 0 | AX26: =IFERROR(O26,AF26) -> #N/A
A27: VLOOKUP NAMA | B27: P2 | C27: KENDAL | D27: 1063120250204926 | E27: Sumarno | F27: Konsumen Aktif M 0 - 6 Lunas | G27: =VLOOKUP(D27,'DATABASE RO'!$B$3:$M$299,4,0) -> #N/A | H27: =VLOOKUP(D27,'DATABASE RO'!$B$3:$M$299,5,0) -> #N/A | I27: =VLOOKUP(D27,'DATABASE RO'!$B$3:$M$299,6,0) -> #N/A | J27: =VLOOKUP(D27,'DATABASE RO'!$B$3:$M$299,7,0) -> #N/A | K27: =VLOOKUP(D27,'DATABASE RO'!$B$3:$M$299,8,0) -> #N/A | L27: =VLOOKUP(D27,'DATABASE RO'!$B$3:$M$299,9,0) -> #N/A | M27: =VLOOKUP(D27,'DATABASE RO'!$B$3:$M$299,10,0) -> #N/A | O27: =VLOOKUP(D27,'DATABASE RO'!$B$3:$M$299,12,0) -> #N/A | S27: =B27 -> P2 | T27: =C27 -> KENDAL | U27: =D27 -> 1063120250204926 | V27: =E27 -> Sumarno | X27: =VLOOKUP(V27,'DATABASE RO'!$C$3:$M$185,3,0) -> #N/A | Y27: =VLOOKUP(V27,'DATABASE RO'!$C$3:$M$185,4,0) -> #N/A | Z27: =VLOOKUP(V27,'DATABASE RO'!$C$3:$M$185,5,0) -> #N/A | AA27: =VLOOKUP(V27,'DATABASE RO'!$C$3:$M$185,6,0) -> #N/A | AB27: =VLOOKUP(V27,'DATABASE RO'!$C$3:$M$185,7,0) -> #N/A | AC27: =VLOOKUP(V27,'DATABASE RO'!$C$3:$M$185,8,0) -> #N/A | AD27: =VLOOKUP(V27,'DATABASE RO'!$C$3:$M$185,9,0) -> #N/A | AF27: =VLOOKUP(V27,'DATABASE RO'!$C$3:$M$185,11,0) -> #N/A | AJ27: VLOOKUP NAMA | AK27: =B27 -> P2 | AL27: =C27 -> KENDAL | AM27: =D27 -> 1063120250204926 | AN27: =E27 -> Sumarno | AO27: =F27 -> Konsumen Aktif M 0 - 6 Lunas | AP27: =IFERROR(G27,X27) -> #N/A | AQ27: =IFERROR(H27,Y27) -> #N/A | AR27: =IFERROR(I27,Z27) -> #N/A | AS27: =IFERROR(J27,AA27) -> #N/A | AT27: =IFERROR(K27,AB27) -> #N/A | AU27: =IFERROR(L27,AC27) -> #N/A | AV27: =IFERROR(M27,AD27) -> #N/A | AW27: =IFERROR(N27,AE27) -> 0 | AX27: =IFERROR(O27,AF27) -> #N/A
A28: VLOOKUP NAMA | B28: P2 | C28: KENDAL | D28: 1063120250204928 | E28: Eli Finafatul Munawaroh | F28: Konsumen Aktif M 0 - 6 Lunas | G28: =VLOOKUP(D28,'DATABASE RO'!$B$3:$M$299,4,0) -> #N/A | H28: =VLOOKUP(D28,'DATABASE RO'!$B$3:$M$299,5,0) -> #N/A | I28: =VLOOKUP(D28,'DATABASE RO'!$B$3:$M$299,6,0) -> #N/A | J28: =VLOOKUP(D28,'DATABASE RO'!$B$3:$M$299,7,0) -> #N/A | K28: =VLOOKUP(D28,'DATABASE RO'!$B$3:$M$299,8,0) -> #N/A | L28: =VLOOKUP(D28,'DATABASE RO'!$B$3:$M$299,9,0) -> #N/A | M28: =VLOOKUP(D28,'DATABASE RO'!$B$3:$M$299,10,0) -> #N/A | O28: =VLOOKUP(D28,'DATABASE RO'!$B$3:$M$299,12,0) -> #N/A | S28: =B28 -> P2 | T28: =C28 -> KENDAL | U28: =D28 -> 1063120250204928 | V28: =E28 -> Eli Finafatul Munawaroh | X28: =VLOOKUP(V28,'DATABASE RO'!$C$3:$M$185,3,0) -> #N/A | Y28: =VLOOKUP(V28,'DATABASE RO'!$C$3:$M$185,4,0) -> #N/A | Z28: =VLOOKUP(V28,'DATABASE RO'!$C$3:$M$185,5,0) -> #N/A | AA28: =VLOOKUP(V28,'DATABASE RO'!$C$3:$M$185,6,0) -> #N/A | AB28: =VLOOKUP(V28,'DATABASE RO'!$C$3:$M$185,7,0) -> #N/A | AC28: =VLOOKUP(V28,'DATABASE RO'!$C$3:$M$185,8,0) -> #N/A | AD28: =VLOOKUP(V28,'DATABASE RO'!$C$3:$M$185,9,0) -> #N/A | AF28: =VLOOKUP(V28,'DATABASE RO'!$C$3:$M$185,11,0) -> #N/A | AJ28: VLOOKUP NAMA | AK28: =B28 -> P2 | AL28: =C28 -> KENDAL | AM28: =D28 -> 1063120250204928 | AN28: =E28 -> Eli Finafatul Munawaroh | AO28: =F28 -> Konsumen Aktif M 0 - 6 Lunas | AP28: =IFERROR(G28,X28) -> #N/A | AQ28: =IFERROR(H28,Y28) -> #N/A | AR28: =IFERROR(I28,Z28) -> #N/A | AS28: =IFERROR(J28,AA28) -> #N/A | AT28: =IFERROR(K28,AB28) -> #N/A | AU28: =IFERROR(L28,AC28) -> #N/A | AV28: =IFERROR(M28,AD28) -> #N/A | AW28: =IFERROR(N28,AE28) -> 0 | AX28: =IFERROR(O28,AF28) -> #N/A
B29: P2 | C29: KENDAL | D29: 1063120250204930 | E29: ISROPI | F29: Konsumen Aktif M 0 - 6 Lunas | G29: =VLOOKUP(D29,'DATABASE RO'!$B$3:$M$299,4,0) -> CUS063120240608105 | H29: =VLOOKUP(D29,'DATABASE RO'!$B$3:$M$299,5,0) -> YES | I29: =VLOOKUP(D29,'DATABASE RO'!$B$3:$M$299,6,0) -> KEPYAR RT 001 /RW 002, Tlogopayung, Plantungan, KAB-Kendal, 51362 | J29: =VLOOKUP(D29,'DATABASE RO'!$B$3:$M$299,7,0) -> TLOGOPAYUNG | K29: =VLOOKUP(D29,'DATABASE RO'!$B$3:$M$299,8,0) -> PLANTUNGAN | L29: =VLOOKUP(D29,'DATABASE RO'!$B$3:$M$299,9,0) -> https://www.google.com/maps?z=12&t=m&q=loc:-7.119953+109.962283 | M29: =VLOOKUP(D29,'DATABASE RO'!$B$3:$M$299,10,0) -> EXCELLENT | O29: =VLOOKUP(D29,'DATABASE RO'!$B$3:$M$299,12,0) -> 082313738718 | S29: =B29 -> P2 | T29: =C29 -> KENDAL | U29: =D29 -> 1063120250204930 | V29: =E29 -> ISROPI | X29: =VLOOKUP(V29,'DATABASE RO'!$C$3:$M$185,3,0) -> CUS063120240608105 | Y29: =VLOOKUP(V29,'DATABASE RO'!$C$3:$M$185,4,0) -> YES | Z29: =VLOOKUP(V29,'DATABASE RO'!$C$3:$M$185,5,0) -> KEPYAR RT 001 /RW 002, Tlogopayung, Plantungan, KAB-Kendal, 51362 | AA29: =VLOOKUP(V29,'DATABASE RO'!$C$3:$M$185,6,0) -> TLOGOPAYUNG | AB29: =VLOOKUP(V29,'DATABASE RO'!$C$3:$M$185,7,0) -> PLANTUNGAN | AC29: =VLOOKUP(V29,'DATABASE RO'!$C$3:$M$185,8,0) -> https://www.google.com/maps?z=12&t=m&q=loc:-7.119953+109.962283 | AD29: =VLOOKUP(V29,'DATABASE RO'!$C$3:$M$185,9,0) -> EXCELLENT | AF29: =VLOOKUP(V29,'DATABASE RO'!$C$3:$M$185,11,0) -> 082313738718 | AK29: =B29 -> P2 | AL29: =C29 -> KENDAL | AM29: =D29 -> 1063120250204930 | AN29: =E29 -> ISROPI | AO29: =F29 -> Konsumen Aktif M 0 - 6 Lunas | AP29: =IFERROR(G29,X29) -> CUS063120240608105 | AQ29: =IFERROR(H29,Y29) -> YES | AR29: =IFERROR(I29,Z29) -> KEPYAR RT 001 /RW 002, Tlogopayung, Plantungan, KAB-Kendal, 51362 | AS29: =IFERROR(J29,AA29) -> TLOGOPAYUNG | AT29: =IFERROR(K29,AB29) -> PLANTUNGAN | AU29: =IFERROR(L29,AC29) -> https://www.google.com/maps?z=12&t=m&q=loc:-7.119953+109.962283 | AV29: =IFERROR(M29,AD29) -> EXCELLENT | AW29: =IFERROR(N29,AE29) -> 0 | AX29: =IFERROR(O29,AF29) -> 082313738718
A30: VLOOKUP NAMA | B30: P2 | C30: KENDAL | D30: 1063120250304942 | E30: DWI TJONDRO SULISTIYOWATI | F30: Konsumen Aktif M 0 - 6 Lunas | G30: =VLOOKUP(D30,'DATABASE RO'!$B$3:$M$299,4,0) -> #N/A | H30: =VLOOKUP(D30,'DATABASE RO'!$B$3:$M$299,5,0) -> #N/A | I30: =VLOOKUP(D30,'DATABASE RO'!$B$3:$M$299,6,0) -> #N/A | J30: =VLOOKUP(D30,'DATABASE RO'!$B$3:$M$299,7,0) -> #N/A | K30: =VLOOKUP(D30,'DATABASE RO'!$B$3:$M$299,8,0) -> #N/A | L30: =VLOOKUP(D30,'DATABASE RO'!$B$3:$M$299,9,0) -> #N/A | M30: =VLOOKUP(D30,'DATABASE RO'!$B$3:$M$299,10,0) -> #N/A | O30: =VLOOKUP(D30,'DATABASE RO'!$B$3:$M$299,12,0) -> #N/A | S30: =B30 -> P2 | T30: =C30 -> KENDAL | U30: =D30 -> 1063120250304942 | V30: =E30 -> DWI TJONDRO SULISTIYOWATI | X30: =VLOOKUP(V30,'DATABASE RO'!$C$3:$M$185,3,0) -> #N/A | Y30: =VLOOKUP(V30,'DATABASE RO'!$C$3:$M$185,4,0) -> #N/A | Z30: =VLOOKUP(V30,'DATABASE RO'!$C$3:$M$185,5,0) -> #N/A | AA30: =VLOOKUP(V30,'DATABASE RO'!$C$3:$M$185,6,0) -> #N/A | AB30: =VLOOKUP(V30,'DATABASE RO'!$C$3:$M$185,7,0) -> #N/A | AC30: =VLOOKUP(V30,'DATABASE RO'!$C$3:$M$185,8,0) -> #N/A | AD30: =VLOOKUP(V30,'DATABASE RO'!$C$3:$M$185,9,0) -> #N/A | AF30: =VLOOKUP(V30,'DATABASE RO'!$C$3:$M$185,11,0) -> #N/A | AJ30: VLOOKUP NAMA | AK30: =B30 -> P2 | AL30: =C30 -> KENDAL | AM30: =D30 -> 1063120250304942 | AN30: =E30 -> DWI TJONDRO SULISTIYOWATI | AO30: =F30 -> Konsumen Aktif M 0 - 6 Lunas | AP30: =IFERROR(G30,X30) -> #N/A | AQ30: =IFERROR(H30,Y30) -> #N/A | AR30: =IFERROR(I30,Z30) -> #N/A | AS30: =IFERROR(J30,AA30) -> #N/A | AT30: =IFERROR(K30,AB30) -> #N/A | AU30: =IFERROR(L30,AC30) -> #N/A | AV30: =IFERROR(M30,AD30) -> #N/A | AW30: =IFERROR(N30,AE30) -> 0 | AX30: =IFERROR(O30,AF30) -> #N/A
A31: VLOOKUP NAMA | B31: P2 | C31: KENDAL | D31: 1063120250304964 | E31: SURYANTO | F31: Konsumen Aktif M 0 - 6 Lunas | G31: =VLOOKUP(D31,'DATABASE RO'!$B$3:$M$299,4,0) -> #N/A | H31: =VLOOKUP(D31,'DATABASE RO'!$B$3:$M$299,5,0) -> #N/A | I31: =VLOOKUP(D31,'DATABASE RO'!$B$3:$M$299,6,0) -> #N/A | J31: =VLOOKUP(D31,'DATABASE RO'!$B$3:$M$299,7,0) -> #N/A | K31: =VLOOKUP(D31,'DATABASE RO'!$B$3:$M$299,8,0) -> #N/A | L31: =VLOOKUP(D31,'DATABASE RO'!$B$3:$M$299,9,0) -> #N/A | M31: =VLOOKUP(D31,'DATABASE RO'!$B$3:$M$299,10,0) -> #N/A | O31: =VLOOKUP(D31,'DATABASE RO'!$B$3:$M$299,12,0) -> #N/A | S31: =B31 -> P2 | T31: =C31 -> KENDAL | U31: =D31 -> 1063120250304964 | V31: =E31 -> SURYANTO | X31: =VLOOKUP(V31,'DATABASE RO'!$C$3:$M$185,3,0) -> #N/A | Y31: =VLOOKUP(V31,'DATABASE RO'!$C$3:$M$185,4,0) -> #N/A | Z31: =VLOOKUP(V31,'DATABASE RO'!$C$3:$M$185,5,0) -> #N/A | AA31: =VLOOKUP(V31,'DATABASE RO'!$C$3:$M$185,6,0) -> #N/A | AB31: =VLOOKUP(V31,'DATABASE RO'!$C$3:$M$185,7,0) -> #N/A | AC31: =VLOOKUP(V31,'DATABASE RO'!$C$3:$M$185,8,0) -> #N/A | AD31: =VLOOKUP(V31,'DATABASE RO'!$C$3:$M$185,9,0) -> #N/A | AF31: =VLOOKUP(V31,'DATABASE RO'!$C$3:$M$185,11,0) -> #N/A | AJ31: VLOOKUP NAMA | AK31: =B31 -> P2 | AL31: =C31 -> KENDAL | AM31: =D31 -> 1063120250304964 | AN31: =E31 -> SURYANTO | AO31: =F31 -> Konsumen Aktif M 0 - 6 Lunas | AP31: =IFERROR(G31,X31) -> #N/A | AQ31: =IFERROR(H31,Y31) -> #N/A | AR31: =IFERROR(I31,Z31) -> #N/A | AS31: =IFERROR(J31,AA31) -> #N/A | AT31: =IFERROR(K31,AB31) -> #N/A | AU31: =IFERROR(L31,AC31) -> #N/A | AV31: =IFERROR(M31,AD31) -> #N/A | AW31: =IFERROR(N31,AE31) -> 0 | AX31: =IFERROR(O31,AF31) -> #N/A
B32: P2 | C32: KENDAL | D32: 1063120250404995 | E32: NURSALIM | F32: Konsumen Aktif M 0 - 6 Lunas | G32: =VLOOKUP(D32,'DATABASE RO'!$B$3:$M$299,4,0) -> P19002062843 | H32: =VLOOKUP(D32,'DATABASE RO'!$B$3:$M$299,5,0) -> YES | I32: =VLOOKUP(D32,'DATABASE RO'!$B$3:$M$299,6,0) -> Krajan RT 003 /RW 001, Karanganyar, Plantungan, KAB-Kendal, 51362 | J32: =VLOOKUP(D32,'DATABASE RO'!$B$3:$M$299,7,0) -> Karanganyar | K32: =VLOOKUP(D32,'DATABASE RO'!$B$3:$M$299,8,0) -> Plantungan | L32: =VLOOKUP(D32,'DATABASE RO'!$B$3:$M$299,9,0) -> https://www.google.com/maps?z=12&t=m&q=loc:-7.079079+109.987101 | M32: =VLOOKUP(D32,'DATABASE RO'!$B$3:$M$299,10,0) -> GOOD | O32: =VLOOKUP(D32,'DATABASE RO'!$B$3:$M$299,12,0) -> 0877 - 11036604 | S32: =B32 -> P2 | T32: =C32 -> KENDAL | U32: =D32 -> 1063120250404995 | V32: =E32 -> NURSALIM | X32: =VLOOKUP(V32,'DATABASE RO'!$C$3:$M$185,3,0) -> P19002062843 | Y32: =VLOOKUP(V32,'DATABASE RO'!$C$3:$M$185,4,0) -> YES | Z32: =VLOOKUP(V32,'DATABASE RO'!$C$3:$M$185,5,0) -> Krajan RT 003 /RW 001, Karanganyar, Plantungan, KAB-Kendal, 51362 | AA32: =VLOOKUP(V32,'DATABASE RO'!$C$3:$M$185,6,0) -> Karanganyar | AB32: =VLOOKUP(V32,'DATABASE RO'!$C$3:$M$185,7,0) -> Plantungan | AC32: =VLOOKUP(V32,'DATABASE RO'!$C$3:$M$185,8,0) -> https://www.google.com/maps?z=12&t=m&q=loc:-7.079079+109.987101 | AD32: =VLOOKUP(V32,'DATABASE RO'!$C$3:$M$185,9,0) -> GOOD | AF32: =VLOOKUP(V32,'DATABASE RO'!$C$3:$M$185,11,0) -> 0877 - 11036604 | AK32: =B32 -> P2 | AL32: =C32 -> KENDAL | AM32: =D32 -> 1063120250404995 | AN32: =E32 -> NURSALIM | AO32: =F32 -> Konsumen Aktif M 0 - 6 Lunas | AP32: =IFERROR(G32,X32) -> P19002062843 | AQ32: =IFERROR(H32,Y32) -> YES | AR32: =IFERROR(I32,Z32) -> Krajan RT 003 /RW 001, Karanganyar, Plantungan, KAB-Kendal, 51362 | AS32: =IFERROR(J32,AA32) -> Karanganyar | AT32: =IFERROR(K32,AB32) -> Plantungan | AU32: =IFERROR(L32,AC32) -> https://www.google.com/maps?z=12&t=m&q=loc:-7.079079+109.987101 | AV32: =IFERROR(M32,AD32) -> GOOD | AW32: =IFERROR(N32,AE32) -> 0 | AX32: =IFERROR(O32,AF32) -> 0877 - 11036604
B33: P2 | C33: KENDAL | D33: 1063120250505020 | E33: SITI ROYATUN | F33: Konsumen Aktif M 0 - 6 Lunas | G33: =VLOOKUP(D33,'DATABASE RO'!$B$3:$M$299,4,0) -> P19002064959 | H33: =VLOOKUP(D33,'DATABASE RO'!$B$3:$M$299,5,0) -> YES | I33: =VLOOKUP(D33,'DATABASE RO'!$B$3:$M$299,6,0) -> DUSUN GLANDANG RT 001 /RW 004, Kedungsuren, Kaliwungu Selatan, KAB-Kendal, 51372 | J33: =VLOOKUP(D33,'DATABASE RO'!$B$3:$M$299,7,0) -> Kedungsuren | K33: =VLOOKUP(D33,'DATABASE RO'!$B$3:$M$299,8,0) -> Kaliwungu Selatan | L33: =VLOOKUP(D33,'DATABASE RO'!$B$3:$M$299,9,0) -> TIDAK ADA | M33: =VLOOKUP(D33,'DATABASE RO'!$B$3:$M$299,10,0) -> EXCELLENT | O33: =VLOOKUP(D33,'DATABASE RO'!$B$3:$M$299,12,0) -> 0882 - 008249080 | S33: =B33 -> P2 | T33: =C33 -> KENDAL | U33: =D33 -> 1063120250505020 | V33: =E33 -> SITI ROYATUN | X33: =VLOOKUP(V33,'DATABASE RO'!$C$3:$M$185,3,0) -> P19002064959 | Y33: =VLOOKUP(V33,'DATABASE RO'!$C$3:$M$185,4,0) -> YES | Z33: =VLOOKUP(V33,'DATABASE RO'!$C$3:$M$185,5,0) -> DUSUN GLANDANG RT 001 /RW 004, Kedungsuren, Kaliwungu Selatan, KAB-Kendal, 51372 | AA33: =VLOOKUP(V33,'DATABASE RO'!$C$3:$M$185,6,0) -> Kedungsuren | AB33: =VLOOKUP(V33,'DATABASE RO'!$C$3:$M$185,7,0) -> Kaliwungu Selatan | AC33: =VLOOKUP(V33,'DATABASE RO'!$C$3:$M$185,8,0) -> TIDAK ADA | AD33: =VLOOKUP(V33,'DATABASE RO'!$C$3:$M$185,9,0) -> EXCELLENT | AF33: =VLOOKUP(V33,'DATABASE RO'!$C$3:$M$185,11,0) -> 0882 - 008249080 | AK33: =B33 -> P2 | AL33: =C33 -> KENDAL | AM33: =D33 -> 1063120250505020 | AN33: =E33 -> SITI ROYATUN | AO33: =F33 -> Konsumen Aktif M 0 - 6 Lunas | AP33: =IFERROR(G33,X33) -> P19002064959 | AQ33: =IFERROR(H33,Y33) -> YES | AR33: =IFERROR(I33,Z33) -> DUSUN GLANDANG RT 001 /RW 004, Kedungsuren, Kaliwungu Selatan, KAB-Kendal, 51372 | AS33: =IFERROR(J33,AA33) -> Kedungsuren | AT33: =IFERROR(K33,AB33) -> Kaliwungu Selatan | AU33: =IFERROR(L33,AC33) -> TIDAK ADA | AV33: =IFERROR(M33,AD33) -> EXCELLENT | AW33: =IFERROR(N33,AE33) -> 0 | AX33: =IFERROR(O33,AF33) -> 0882 - 008249080
B34: P2 | C34: KENDAL | D34: 1063120250505029 | E34: Minayati setiani | F34: Konsumen Aktif M 0 - 6 Lunas | G34: =VLOOKUP(D34,'DATABASE RO'!$B$3:$M$299,4,0) -> CUS063120210905347 | H34: =VLOOKUP(D34,'DATABASE RO'!$B$3:$M$299,5,0) -> NO | I34: =VLOOKUP(D34,'DATABASE RO'!$B$3:$M$299,6,0) -> BUMIAYU RT 008 /RW 003, Bumiayu, Weleri, KAB-Kendal, 51355 | J34: =VLOOKUP(D34,'DATABASE RO'!$B$3:$M$299,7,0) -> Balok | K34: =VLOOKUP(D34,'DATABASE RO'!$B$3:$M$299,8,0) -> Kendal | L34: =VLOOKUP(D34,'DATABASE RO'!$B$3:$M$299,9,0) -> https://www.google.com/maps?z=12&t=m&q=loc:-6.980049+110.073777 | M34: =VLOOKUP(D34,'DATABASE RO'!$B$3:$M$299,10,0) -> EXCELLENT | O34: =VLOOKUP(D34,'DATABASE RO'!$B$3:$M$299,12,0) -> 081904757492 | S34: =B34 -> P2 | T34: =C34 -> KENDAL | U34: =D34 -> 1063120250505029 | V34: =E34 -> Minayati setiani | X34: =VLOOKUP(V34,'DATABASE RO'!$C$3:$M$185,3,0) -> CUS063120210905347 | Y34: =VLOOKUP(V34,'DATABASE RO'!$C$3:$M$185,4,0) -> NO | Z34: =VLOOKUP(V34,'DATABASE RO'!$C$3:$M$185,5,0) -> BUMIAYU RT 008 /RW 003, Bumiayu, Weleri, KAB-Kendal, 51355 | AA34: =VLOOKUP(V34,'DATABASE RO'!$C$3:$M$185,6,0) -> Balok | AB34: =VLOOKUP(V34,'DATABASE RO'!$C$3:$M$185,7,0) -> Kendal | AC34: =VLOOKUP(V34,'DATABASE RO'!$C$3:$M$185,8,0) -> https://www.google.com/maps?z=12&t=m&q=loc:-6.980049+110.073777 | AD34: =VLOOKUP(V34,'DATABASE RO'!$C$3:$M$185,9,0) -> EXCELLENT | AF34: =VLOOKUP(V34,'DATABASE RO'!$C$3:$M$185,11,0) -> 081904757492 | AK34: =B34 -> P2 | AL34: =C34 -> KENDAL | AM34: =D34 -> 1063120250505029 | AN34: =E34 -> Minayati setiani | AO34: =F34 -> Konsumen Aktif M 0 - 6 Lunas | AP34: =IFERROR(G34,X34) -> CUS063120210905347 | AQ34: =IFERROR(H34,Y34) -> NO | AR34: =IFERROR(I34,Z34) -> BUMIAYU RT 008 /RW 003, Bumiayu, Weleri, KAB-Kendal, 51355 | AS34: =IFERROR(J34,AA34) -> Balok | AT34: =IFERROR(K34,AB34) -> Kendal | AU34: =IFERROR(L34,AC34) -> https://www.google.com/maps?z=12&t=m&q=loc:-6.980049+110.073777 | AV34: =IFERROR(M34,AD34) -> EXCELLENT | AW34: =IFERROR(N34,AE34) -> 0 | AX34: =IFERROR(O34,AF34) -> 081904757492
B35: P2 | C35: KENDAL | D35: 1063120250505033 | E35: Listiyo hardiman | F35: Konsumen Aktif M 0 - 6 Lunas | G35: =VLOOKUP(D35,'DATABASE RO'!$B$3:$M$299,4,0) -> CUS063120210805233 | H35: =VLOOKUP(D35,'DATABASE RO'!$B$3:$M$299,5,0) -> NO | I35: =VLOOKUP(D35,'DATABASE RO'!$B$3:$M$299,6,0) -> TRIDI RT 007 /RW 003, Dempelrejo, Ngampel, KENDAL, 51357 | J35: =VLOOKUP(D35,'DATABASE RO'!$B$3:$M$299,7,0) -> Dempelrejo | K35: =VLOOKUP(D35,'DATABASE RO'!$B$3:$M$299,8,0) -> Ngampel | L35: =VLOOKUP(D35,'DATABASE RO'!$B$3:$M$299,9,0) -> https://www.google.com/maps?z=12&t=m&q=loc:-6.954715+110.200846 | M35: =VLOOKUP(D35,'DATABASE RO'!$B$3:$M$299,10,0) -> NORMAL | O35: =VLOOKUP(D35,'DATABASE RO'!$B$3:$M$299,12,0) -> 089653350080 | S35: =B35 -> P2 | T35: =C35 -> KENDAL | U35: =D35 -> 1063120250505033 | V35: =E35 -> Listiyo hardiman | X35: =VLOOKUP(V35,'DATABASE RO'!$C$3:$M$185,3,0) -> CUS063120210805233 | Y35: =VLOOKUP(V35,'DATABASE RO'!$C$3:$M$185,4,0) -> NO | Z35: =VLOOKUP(V35,'DATABASE RO'!$C$3:$M$185,5,0) -> TRIDI RT 007 /RW 003, Dempelrejo, Ngampel, KENDAL, 51357 | AA35: =VLOOKUP(V35,'DATABASE RO'!$C$3:$M$185,6,0) -> Dempelrejo | AB35: =VLOOKUP(V35,'DATABASE RO'!$C$3:$M$185,7,0) -> Ngampel | AC35: =VLOOKUP(V35,'DATABASE RO'!$C$3:$M$185,8,0) -> https://www.google.com/maps?z=12&t=m&q=loc:-6.954715+110.200846 | AD35: =VLOOKUP(V35,'DATABASE RO'!$C$3:$M$185,9,0) -> NORMAL | AF35: =VLOOKUP(V35,'DATABASE RO'!$C$3:$M$185,11,0) -> 089653350080 | AK35: =B35 -> P2 | AL35: =C35 -> KENDAL | AM35: =D35 -> 1063120250505033 | AN35: =E35 -> Listiyo hardiman | AO35: =F35 -> Konsumen Aktif M 0 - 6 Lunas | AP35: =IFERROR(G35,X35) -> CUS063120210805233 | AQ35: =IFERROR(H35,Y35) -> NO | AR35: =IFERROR(I35,Z35) -> TRIDI RT 007 /RW 003, Dempelrejo, Ngampel, KENDAL, 51357 | AS35: =IFERROR(J35,AA35) -> Dempelrejo | AT35: =IFERROR(K35,AB35) -> Ngampel | AU35: =IFERROR(L35,AC35) -> https://www.google.com/maps?z=12&t=m&q=loc:-6.954715+110.200846 | AV35: =IFERROR(M35,AD35) -> NORMAL | AW35: =IFERROR(N35,AE35) -> 0 | AX35: =IFERROR(O35,AF35) -> 089653350080
